Workbook

Sheet APPLICANTS 2023
A1: Reg No | B1: NAME | C1: FATHER'S NAME | D1: DOB | E1: AGE | F1: I. NO | G1: INSTITUTION | H1: ADDRESS | I1: TOWN | J1: DISTRICT | K1: PINCODE | L1: EMAIL | M1: CONTACT No. P | N1: CONTACT No. M | O1: MEMORIZED JUZUS | P1: CATEGORY | Q1: JUZU SELECTION
A2: 3034 | B2: Mohamed Miyaz S.M.F | C2: Seyed Mohamed Firdous | D2: 40328 | E2: =("03-11-2023"-D2)/365.25 -> 13.429158 | F2: =VLOOKUP(G2,'MADRASA LIST'!A:J,9,FALSE) -> 64 | G2: Wisdom Public School | H2: Kayalpatnam | I2: Kayalpatnam | J2: Thoothukudi | K2: 628204 | L2: firdous77@gmail.com | M2: 9629923889 | N2: 6381493489 | O2: 30 | P2: 30
A3: 3055 | B3: Nabeel S | C3: Sulthan | D3: 40334 | E3: =("03-11-2023"-D3)/365.25 -> 13.412731 | F3: =VLOOKUP(G3,'MADRASA LIST'!A:J,9,FALSE) -> 63 | G3: SFTC Tutorial & Tution Centre | H3: Kayalpatnam | I3: Kayalpatnam | J3: Thoothukudi | K3: 628204 | M3: 8925164535 | N3: 9750374318 | O3: 30 | P3: 30
A4: 3021 | B4: Hameed Afnaan M M | C4: Mohammed Mohiddin | D4: 40335 | E4: =("03-11-2023"-D4)/365.25 -> 13.409993 | F4: =VLOOKUP(G4,'MADRASA LIST'!A:J,9,FALSE) -> 58 | G4: L.K.Higher Secondary School | H4: Kayalpatnam | I4: Kayalpatnam | J4: Thoothukudi | K4: 628204 | M4: 9486228661 | O4: 30 | P4: 30
A5: 3003 | B5: Abdul Kader Mufees P.M | C5: Peer Mohamed M.A | D5: 39858 | E5: =("03-11-2023"-D5)/365.25 -> 14.715948 | F5: =VLOOKUP(G5,'MADRASA LIST'!A:J,9,FALSE) -> 60 | G5: Madarasathul Azhar Li Thahfeezil Quranil Kareem | H5: Kayalpatnam | I5: Kayalpatnam | J5: Thoothukudi | K5: 628204 | M5: 7418811626 | O5: 30 | P5: 30
A6: 3009 | B6: Abdullah M.S.H | C6: Mohammed Seyed Hashan M.A.K | D6: 39592 | E6: =("03-11-2023"-D6)/365.25 -> 15.444216 | F6: =VLOOKUP(G6,'MADRASA LIST'!A:J,9,FALSE) -> 06 | G6: Measi Matriculation Hr Sec School | H6: 113, Angappan Street, Mannady | I6: Chennai | J6: Chennai | K6: 600001 | L6: info@measischool.edu.in | M6: 9952507935 | N6: 9941579786 | O6: 30 | P6: 30
A7: 3015 | B7: Ahamed Ibrahim R | C7: Rafeek MuhamedMusthafa | D7: 39793 | E7: =("03-11-2023"-D7)/365.25 -> 14.893908 | F7: =VLOOKUP(G7,'MADRASA LIST'!A:J,9,FALSE) -> 63 | G7: SFTC Tutorial & Tution Centre | H7: Kayalpatnam | I7: Kayalpatnam | J7: Thoothukudi | K7: 628204 | L7: aimmusthafa480@gmail.com | M7: 9994353480 | N7: 9750374318 | O7: 30 | P7: 30
A8: 1512 | B8: Ahamed Ikraam R | C8: Rafeek MuhamedMusthafa | D8: 40621 | E8: =("03-11-2023"-D8)/365.25 -> 12.626968 | F8: =VLOOKUP(G8,'MADRASA LIST'!A:J,9,FALSE) -> 63 | G8: SFTC Tutorial & Tution Centre | H8: Kayalpatnam | I8: Kayalpatnam | J8: Thoothukudi | K8: 628204 | L8: aimmusthafa480@gmail.com | M8: 9994353480 | N8: 9750374318 | P8: 15 | Q8: (26-30) `hkPk; (حم) Kjy; mk;k (عَمَّ) tiu> (1-10) myp/g; yhk; kPk; (آلم) Kjy; t/yK (وَٱعْلَمُواْ) tiu
A9: 506 | B9: Abdur Rahman A.R | C9: Abdul Raheem M.H | D9: 41604 | E9: =("03-11-2023"-D9)/365.25 -> 9.9356605 | F9: =VLOOKUP(G9,'MADRASA LIST'!A:J,9,FALSE) -> 59 | G9: L.K.Primary School | H9: Kayalpatnam | I9: Kayalpatnam | J9: Thoothukudi | K9: 628204 | M9: 9842372944 | O9: 11 | P9: 5 | Q9: (26-30) `hkPk; (حم) Kjy; mk;k (عَمَّ) tiu
A10: 512 | B10: Ahnaf T.A | C10: Thameem Ansari T | D10: 41112 | E10: =("03-11-2023"-D10)/365.25 -> 11.282683 | F10: =VLOOKUP(G10,'MADRASA LIST'!A:J,9,FALSE) -> 60 | G10: Madarasathul Azhar Li Thahfeezil Quranil Kareem | H10: Kayalpatnam | I10: Kayalpatnam | J10: Thoothukudi | K10: 628204 | M10: 9940905119 | O10: 12 | P10: 5 | Q10: (26-30) `hkPk; (حم) Kjy; mk;k (عَمَّ) tiu
A11: 517 | B11: Anas Abdullah M.A | C11: Mogudoom Alaudeen H.M.F | D11: 41236 | E11: =("03-11-2023"-D11)/365.25 -> 10.94319 | F11: =VLOOKUP(G11,'MADRASA LIST'!A:J,9,FALSE) -> 60 | G11: Madarasathul Azhar Li Thahfeezil Quranil Kareem | H11: Kayalpatnam | I11: Kayalpatnam | J11: Thoothukudi | K11: 628204 | M11: 8903115315 | O11: 15 | P11: 5 | Q11: (26-30) `hkPk; (حم) Kjy; mk;k (عَمَّ) tiu
A12: 1502 | B12: Abdul Muiz | C12: Seyed Muhyiddeen | D12: 40748 | E12: =("03-11-2023"-D12)/365.25 -> 12.279261 | F12: =VLOOKUP(G12,'MADRASA LIST'!A:J,9,FALSE) -> 60 | G12: Madarasathul Azhar Li Thahfeezil Quranil Kareem | H12: Kayalpatnam | I12: Kayalpatnam | J12: Thoothukudi | K12: 628204 | L12: seyedmohideen@gmail.com | M12: 7539976409 | O12: 16 | P12: 15 | Q12: (26-30) `hkPk; (حم) Kjy; mk;k (عَمَّ) tiu> (1-10) myp/g; yhk; kPk; (آلم) Kjy; t/yK (وَٱعْلَمُواْ) tiu
A13: 1506 | B13: Abdullah Mackie G.M | C13: Gani Muhammad M.A | D13: 40810 | E13: =("03-11-2023"-D13)/365.25 -> 12.109514 | F13: =VLOOKUP(G13,'MADRASA LIST'!A:J,9,FALSE) -> 60 | G13: Madarasathul Azhar Li Thahfeezil Quranil Kareem | H13: Kayalpatnam | I13: Kayalpatnam | J13: Thoothukudi | K13: 628204 | L13: gani3477@gmail.com | M13: 8122565545 | O13: 15 | P13: 15 | Q13: (26-30) `hkPk; (حم) Kjy; mk;k (عَمَّ) tiu> (1-10) myp/g; yhk; kPk; (آلم) Kjy; t/yK (وَٱعْلَمُواْ) tiu
A14: 503 | B14: Abdul Kaathir J.M | C14: Jamal Mohamed A.K | D14: 40995 | E14: =("03-11-2023"-D14)/365.25 -> 11.603012 | F14: =VLOOKUP(G14,'MADRASA LIST'!A:J,9,FALSE) -> 58 | G14: L.K.Higher Secondary School | H14: Kayalpatnam | I14: Kayalpatnam | J14: Thoothukudi | K14: 628204 | M14: 8015707756 | O14: 10 | P14: 5 | Q14: (26-30) `hkPk; (حم) Kjy; mk;k (عَمَّ) tiu
A15: 511 | B15: Ahmed Ibrahim S | C15: Sahul Hameed | D15: 40935 | E15: =("03-11-2023"-D15)/365.25 -> 11.767283 | F15: =VLOOKUP(G15,'MADRASA LIST'!A:J,9,FALSE) -> 58 | G15: L.K.Higher Secondary School | H15: Kayalpatnam | I15: Kayalpatnam | J15: Thoothukudi | K15: 628204 | L15: mkshameed7278@gmail.com | M15: 9944971627 | O15: 6 | P15: 5 | Q15: (26-30) `hkPk; (حم) Kjy; mk;k (عَمَّ) tiu
A16: 3041 | B16: Mohammed Hisham A | C16: Azmathullah A | D16: 39595 | E16: =("03-11-2023"-D16)/365.25 -> 15.436003 | F16: =VLOOKUP(G16,'MADRASA LIST'!A:J,9,FALSE) -> 70 | G16: Iqra Matric Hr Sec School | H16: Oomerabad | I16: Oomerabad | J16: Vellore | K16: 635808 | L16: abuhisham114@gmail.com | M16: 9952080380 | N16: 8148563200 | O16: 30 | P16: 30
A17: 3002 | B17: Abdul Hameed M | C17: Mohamed Yusuf | D17: 39884 | E17: =("03-11-2023"-D17)/365.25 -> 14.644764 | F17: =VLOOKUP(G17,'MADRASA LIST'!A:J,9,FALSE) -> 15 | G17: The New John Dewey Mat High School | H17: 65/29, Kasthuribai Street | I17: Panruti | J17: Cuddalore | K17: 607106 | M17: 7845275458 | O17: 30 | P17: 30
A18: 522 | B18: Haamidh M | C18: Mohamed Tavakkalbadusa | D18: 41788 | E18: =("03-11-2023"-D18)/365.25 -> 9.431896 | F18: =VLOOKUP(G18,'MADRASA LIST'!A:J,9,FALSE) -> 33 | G18: Bright Islamic School | H18: Vaniyar Street | I18: Karambakkudi | J18: Pudukottai | K18: 622302 | M18: 936033644,9943437338 | N18: 936033644,9943437338 | P18: 5 | Q18: (1-5) myp/g; yhk; kPk; (آلم) Kjy; ty;K`;]dhj;J (وَٱلْمُحْصَنَاتُ) tiu
A19: 1540 | B19: Nijardeen T | C19: Tajdeen | D19: 40571 | E19: =("03-11-2023"-D19)/365.25 -> 12.76386 | F19: =VLOOKUP(G19,'MADRASA LIST'!A:J,9,FALSE) -> 33 | G19: Bright Islamic School | H19: Vaniyar Street | I19: Karambakkudi | J19: Pudukottai | K19: 622302 | M19: 936033644,9943437338 | N19: 936033644,9943437338 | O19: 20 | P19: 15 | Q19: (1-15) myp/g; yhk; kPk; (آلم) Kjy; ]{g;`hdy;yjP (سُبْحَانَ ٱلَّذِى) tiu
A20: 1516 | B20: Amanullah Hubaib I | C20: Imdadullah A | D20: 42249 | E20: =("03-11-2023"-D20)/365.25 -> 8.1697467 | F20: =VLOOKUP(G20,'MADRASA LIST'!A:J,9,FALSE) -> 57 | G20: Al Makthabathul Magudhoomiyya | H20: Kayalpatnam | I20: Kayalpatnam | J20: Thoothukudi | K20: 628204 | L20: hunaifimdad@gmail.com | M20: 9414072740 | N20: 9842891960 | O20: 30 | P20: 15 | Q20: (1-15) myp/g; yhk; kPk; (آلم) Kjy; ]{g;`hdy;yjP (سُبْحَانَ ٱلَّذِى) tiu
A21: 564 | B21: Zaahid Buhary | C21: Mohamed Ziyad | D21: 41204 | E21: =("03-11-2023"-D21)/365.25 -> 11.030801 | F21: =VLOOKUP(G21,'MADRASA LIST'!A:J,9,FALSE) -> 64 | G21: Wisdom Public School | H21: Kayalpatnam | I21: Kayalpatnam | J21: Thoothukudi | K21: 628204 | L21: armz84.mohamed@gmail.com | M21: 8056177486 | N21: 6381493489 | O21: 11 | P21: 5 | Q21: (26-30) `hkPk; (حم) Kjy; mk;k (عَمَّ) tiu
A22: 1509 | B22: Abdur Razzaq M | C22: Mujeeb Rahuman M | D22: 41740 | E22: =("03-11-2023"-D22)/365.25 -> 9.5633128 | F22: =VLOOKUP(G22,'MADRASA LIST'!A:J,9,FALSE) -> 28 | G22: Limra Nursery & Primary School | H22: 1020, Villapuram Housing Board | I22: Madurai | J22: Madurai | K22: 625011 | M22: 9790078677 | N22: 8526666344, 9677770854 | O22: 15 | P22: 15 | Q22: (26-30) `hkPk; (حم) Kjy; mk;k (عَمَّ) tiu> (1-10) myp/g; yhk; kPk; (آلم) Kjy; t/yK (وَٱعْلَمُواْ) tiu
A23: 523 | B23: Hassaan S | C23: Sheik Ismail Sathath | D23: 41701 | E23: =("03-11-2023"-D23)/365.25 -> 9.670089 | F23: =VLOOKUP(G23,'MADRASA LIST'!A:J,9,FALSE) -> 28 | G23: Limra Nursery & Primary School | H23: 1020, Villapuram Housing Board | I23: Madurai | J23: Madurai | K23: 625011 | M23: 9865024336 | N23: 8526666344, 9677770854 | O23: 6 | P23: 5 | Q23: (1-5) myp/g; yhk; kPk; (آلم) Kjy; ty;K`;]dhj;J (وَٱلْمُحْصَنَاتُ) tiu
A24: 514 | B24: Ameen M | C24: Mujipur Rahman S | D24: 41447 | E24: =("03-11-2023"-D24)/365.25 -> 10.365503 | F24: =VLOOKUP(G24,'MADRASA LIST'!A:J,9,FALSE) -> 28 | G24: Limra Nursery & Primary School | H24: 1020, Villapuram Housing Board | I24: Madurai | J24: Madurai | K24: 625011 | M24: 9976146128 | N24: 8526666344, 9677770854 | O24: 6 | P24: 5 | Q24: (1-5) myp/g; yhk; kPk; (آلم) Kjy; ty;K`;]dhj;J (وَٱلْمُحْصَنَاتُ) tiu
A25: 504 | B25: Abdullah A | C25: Abdul Nazer V.M | D25: 41198 | E25: =("03-11-2023"-D25)/365.25 -> 11.047228 | F25: =VLOOKUP(G25,'MADRASA LIST'!A:J,9,FALSE) -> 29 | G25: Gift Islamic Academy | H25: Behind SM Oil Company | I25: Gudalur | J25: Nilgris | K25: 643212 | M25: 9443523428 | N25: 04262262727,9443523428 | O25: 29 | P25: 5 | Q25: (1-5) myp/g; yhk; kPk; (آلم) Kjy; ty;K`;]dhj;J (وَٱلْمُحْصَنَاتُ) tiu
A26: 539 | B26: Mohammed Hashfaq A | C26: Abdul Kabeer T.P | D26: 41577 | E26: =("03-11-2023"-D26)/365.25 -> 10.009582 | F26: =VLOOKUP(G26,'MADRASA LIST'!A:J,9,FALSE) -> 29 | G26: Gift Islamic Academy | H26: Behind SM Oil Company | I26: Gudalur | J26: Nilgris | K26: 643212 | M26: 9095026654 | N26: 04262262727,9443523428 | O26: 11 | P26: 5 | Q26: (1-5) myp/g; yhk; kPk; (آلم) Kjy; ty;K`;]dhj;J (وَٱلْمُحْصَنَاتُ) tiu
A27: 1508 | B27: Abdur Rahman A | C27: Abdul Nazer V.M | D27: 40608 | E27: =("03-11-2023"-D27)/365.25 -> 12.66256 | F27: =VLOOKUP(G27,'MADRASA LIST'!A:J,9,FALSE) -> 29 | G27: Gift Islamic Academy | H27: Behind SM Oil Company | I27: Gudalur | J27: Nilgris | K27: 643212 | M27: 9443523428 | N27: 04262262727,9443523428 | O27: 24 | P27: 15 | Q27: (1-15) myp/g; yhk; kPk; (آلم) Kjy; ]{g;`hdy;yjP (سُبْحَانَ ٱلَّذِى) tiu
A28: 3038 | B28: Mohamed Shehin S | C28: Saidalavi | D28: 40593 | E28: =("03-11-2023"-D28)/365.25 -> 12.703628 | F28: =VLOOKUP(G28,'MADRASA LIST'!A:J,9,FALSE) -> 29 | G28: Gift Islamic Academy | H28: Behind SM Oil Company | I28: Gudalur | J28: Nilgris | K28: 643212 | M28: 9442324231 | N28: 04262262727,9443523428 | O28: 30 | P28: 30
A29: 3064 | B29: Syed Hasan S.S | C29: Syed Sajjath H | D29: 40554 | E29: =("03-11-2023"-D29)/365.25 -> 12.810404 | F29: =VLOOKUP(G29,'MADRASA LIST'!A:J,9,FALSE) -> 29 | G29: Gift Islamic Academy | H29: Behind SM Oil Company | I29: Gudalur | J29: Nilgris | K29: 643212 | M29: 9443898140 | N29: 04262262727,9443523428 | O29: 30 | P29: 30
A30: 530 | B30: Mohamed Nuhman S | C30: Samsul Aalam Usmani V.S.M | D30: 41087 | E30: =("03-11-2023"-D30)/365.25 -> 11.351129 | F30: =VLOOKUP(G30,'MADRASA LIST'!A:J,9,FALSE) -> 53 | G30: Madhrasathul Ansar Hifl Madrasa | H30: Gandhi Nagar, Kumili Road | I30: Cumbum | J30: Theni | K30: 625516 | M30: 9655846327 | N30: 7373732829 | O30: 11 | P30: 5 | Q30: (26-30) `hkPk; (حم) Kjy; mk;k (عَمَّ) tiu
A31: 1534 | B31: Muhamed Farhan | C31: Samsudeen | D31: 40653 | E31: =("03-11-2023"-D31)/365.25 -> 12.539357 | F31: =VLOOKUP(G31,'MADRASA LIST'!A:J,9,FALSE) -> 29 | G31: Gift Islamic Academy | H31: Behind SM Oil Company | I31: Gudalur | J31: Nilgris | K31: 643212 | M31: 9443523428 | N31: 04262262727,9443523428 | O31: 20 | P31: 15 | Q31: (1-15) myp/g; yhk; kPk; (آلم) Kjy; ]{g;`hdy;yjP (سُبْحَانَ ٱلَّذِى) tiu
A32: 3006 | B32: Abdulla A.A.C | C32: Ahamed Abdul Cader S.A | D32: 39745 | E32: =("03-11-2023"-D32)/365.25 -> 15.025325 | F32: =VLOOKUP(G32,'MADRASA LIST'!A:J,9,FALSE) -> 64 | G32: Wisdom Public School | H32: Kayalpatnam | I32: Kayalpatnam | J32: Thoothukudi | K32: 628204 | M32: 9894163620 | O32: 30 | P32: 30
A33: 501 | B33: Aaris Mubarak S.A.K | C33: Shaik Abdul Kader M.S.M | D33: 40936 | E33: =("03-11-2023"-D33)/365.25 -> 11.764545 | F33: =VLOOKUP(G33,'MADRASA LIST'!A:J,9,FALSE) -> 64 | G33: Wisdom Public School | H33: Kayalpatnam | I33: Kayalpatnam | J33: Thoothukudi | K33: 628204 | M33: 8754641114 | O33: 5 | P33: 5 | Q33: (26-30) `hkPk; (حم) Kjy; mk;k (عَمَّ) tiu
A34: 3013 | B34: Afkar U.L | C34: Uvaisna Lebbau | D34: 40116 | E34: =("03-11-2023"-D34)/365.25 -> 14.009582 | F34: =VLOOKUP(G34,'MADRASA LIST'!A:J,9,FALSE) -> 60 | G34: Madarasathul Azhar Li Thahfeezil Quranil Kareem | H34: Kayalpatnam | I34: Kayalpatnam | J34: Thoothukudi | K34: 628204 | M34: 9087243222 | O34: 30 | P34: 30
A35: 545 | B35: Mohammed Ummar | C35: Mohammed Akram | D35: 41198 | E35: =("03-11-2023"-D35)/365.25 -> 11.047228 | F35: =VLOOKUP(G35,'MADRASA LIST'!A:J,9,FALSE) -> 67 | G35: Darul Uloom Ahmedi | H35: S.F.No 75/2 C1, Shalimar Tanning Company, Gate No:2, MC Road, Solur | I35: Ambur | J35: Tirupattur | K35: 635814 | M35: 9092637703,9566654598 | N35: 8248752635 | O35: 5 | P35: 5 | Q35: (26-30) `hkPk; (حم) Kjy; mk;k (عَمَّ) tiu
A36: 1541 | B36: Sofi | C36: Mohamed | D36: 39941 | E36: =("03-11-2023"-D36)/365.25 -> 14.488706 | F36: =VLOOKUP(G36,'MADRASA LIST'!A:J,9,FALSE) -> 72 | G36: Madrasa E Imdadiya For The Blind | H36: 540, Anna Salai | I36: Melvisharam | J36: Vellore | K36: 632509 | L36: imdadiya.wes@gmail.com | M36: 9952120340 | N36: 9952120340 | P36: 15 | Q36: (26-30) `hkPk; (حم) Kjy; mk;k (عَمَّ) tiu> (1-10) myp/g; yhk; kPk; (آلم) Kjy; t/yK (وَٱعْلَمُواْ) tiu
A37: 1532 | B37: Mohammed Umaer P | C37: Nasir Ahmed P | D37: 41763 | E37: =("03-11-2023"-D37)/365.25 -> 9.5003422 | F37: =VLOOKUP(G37,'MADRASA LIST'!A:J,9,FALSE) -> 72 | G37: Madrasa E Imdadiya For The Blind | H37: 540, Anna Salai | I37: Melvisharam | J37: Vellore | K37: 632509 | L37: imdadiya.wes@gmail.com | M37: 9952120340 | N37: 9952120340 | P37: 15 | Q37: (26-30) `hkPk; (حم) Kjy; mk;k (عَمَّ) tiu> (1-10) myp/g; yhk; kPk; (آلم) Kjy; t/yK (وَٱعْلَمُواْ) tiu
A38: 3020 | B38: Dasthageer K.M | C38: Ismail K.M | D38: 39905 | E38: =("03-11-2023"-D38)/365.25 -> 14.587269 | F38: =VLOOKUP(G38,'MADRASA LIST'!A:J,9,FALSE) -> 72 | G38: Madrasa E Imdadiya For The Blind | H38: 540, Anna Salai | I38: Melvisharam | J38: Vellore | K38: 632509 | L38: imdadiya.wes@gmail.com | M38: 9952120340 | N38: 9952120340 | O38: 30 | P38: 30
A39: 3063 | B39: Syed Abrarul Haq | C39: Athaullah | D39: 39607 | E39: =("03-11-2023"-D39)/365.25 -> 15.403149 | F39: =VLOOKUP(G39,'MADRASA LIST'!A:J,9,FALSE) -> 72 | G39: Madrasa E Imdadiya For The Blind | H39: 540, Anna Salai | I39: Melvisharam | J39: Vellore | K39: 632509 | L39: imdadiya.wes@gmail.com | M39: 9952120340 | N39: 9952120340 | O39: 30 | P39: 30
A40: 543 | B40: Mohammed Omer Hassan K.R | C40: Nazim Hussain K.R | D40: 41031 | E40: =("03-11-2023"-D40)/365.25 -> 11.504449 | F40: =VLOOKUP(G40,'MADRASA LIST'!A:J,9,FALSE) -> 72 | G40: Madrasa E Imdadiya For The Blind | H40: 540, Anna Salai | I40: Melvisharam | J40: Vellore | K40: 632509 | L40: imdadiya.wes@gmail.com | M40: 9952120340 | N40: 9952120340 | P40: 5 | Q40: (26-30) `hkPk; (حم) Kjy; mk;k (عَمَّ) tiu
...

Sheet MADRASA LIST
A1: INSTITUTION | G1: Email | H1: DISTRICT | I1: NO | J1: NO. OF STUDENTS
A2: Bilal Madrasa For Memorizing Quran | B2: 20, First Floor, Perambur High Road, Jamalia | C2: Chennai | D2: Chennai | E2: 600012 | F2: 9952281255 | H2: Chennai | I2: 01 | J2: =COUNTIF('APPLICANTS 2023'!G:G,A2) -> 4
A3: Dar-Ul-Quranul Kareem (Academy) | B3: Baradhi Nagar, No:8, 7th Street, Korukkupet | C3: Chennai | D3: Chennai | E3: 600001 | F3: 8217300293 | H3: Chennai | I3: 02 | J3: =COUNTIF('APPLICANTS 2023'!G:G,A3) -> 1
A4: Ibnu Taimiyyah Institute For Hifz & Islamic Studies With Academics (Resi) | B4: 1/653A, Kurrathul Aini House, Annai Teresa St, Naduveerapattu | C4: Chennai | D4: Chennai | E4: 600063 | F4: 9790836773 | G4: markazibnutaimiyyah@gmail.com | H4: Chennai | I4: 03 | J4: =COUNTIF('APPLICANTS 2023'!G:G,A4) -> 2
A5: Kilakarai Bukhari Aalim Arabic College | B5: Crescent Campus, GST Road, Vandalur | C5: Chennai | D5: Chennai | E5: 600048 | F5: 8015186332 | H5: Chennai | I5: 04 | J5: =COUNTIF('APPLICANTS 2023'!G:G,A5) -> 1
A6: Madrasa Ubai Ibn Ka'b | B6: 10A, 5th Street, Teeds Garden, Perambur | C6: Chennai | D6: Chennai | E6: 600011 | F6: 7401251027 | H6: Chennai | I6: 05 | J6: =COUNTIF('APPLICANTS 2023'!G:G,A6) -> 2
A7: Measi Matriculation Hr Sec School | B7: 113, Angappan Street,Mannady | C7: Chennai | D7: Chennai | E7: 600001 | F7: 9941579786 | G7: info@measischool.edu.in | H7: Chennai | I7: 06 | J7: =COUNTIF('APPLICANTS 2023'!G:G,A7) -> 1
A8: Sana Model School | B8: 4/122,Goparasanallur,Kattupakkam | C8: Chennai | D8: Chennai | E8: 600056 | F8: 9941786891 | H8: Chennai | I8: 07 | J8: =COUNTIF('APPLICANTS 2023'!G:G,A8) -> 3
A9: Sana Nursery & Primary School | B9: 6, Varadarajulu Street (Near Dasaprakash Hotel) | C9: Egmore | D9: Chennai | E9: 600008 | F9: 8610034441 | H9: Chennai | I9: 08 | J9: =COUNTIF('APPLICANTS 2023'!G:G,A9) -> 1
A10: Sana Smart Matriculation School | B10: 13/13B, Perambur High Road, 1st Street, Jamalia | C10: Chennai | D10: Chennai | E10: 600012 | F10: 9941786891 | G10: adminjamalia@sanamodelschool.com | H10: Chennai | I10: 09 | J10: =COUNTIF('APPLICANTS 2023'!G:G,A10) -> 1
A11: Unity Public School | B11: 109,Lake View Road, Kottur | C11: Chennai | D11: Chennai | E11: 600085 | F11: 8807248712,04424451244/33 | H11: Chennai | I11: 10 | J11: =COUNTIF('APPLICANTS 2023'!G:G,A11) -> 6
A12: Madrasathul Salaful Saliheen | B12: JAQH Masjid | C12: Anamalai | D12: Coimbatore | E12: 642104 | F12: 9942384605 | H12: Coimbatore | I12: 11 | J12: =COUNTIF('APPLICANTS 2023'!G:G,A12) -> 1
A13: Pristine Public School | B13: 371/2, Podanur Main Road | C13: Coimbatore | D13: Coimbatore | E13: 641023 | F13: 8220143927 | H13: Coimbatore | I13: 12 | J13: =COUNTIF('APPLICANTS 2023'!G:G,A13) -> 5
A14: Al Madrasathul Mahmoodiya | B14: Jamia Masjid, Meerapalli | C14: Parangipettai | D14: Cuddalore | E14: 608502 | F14: 8925656621 | H14: Cuddalore | I14: 13 | J14: =COUNTIF('APPLICANTS 2023'!G:G,A14) -> 3
A15: Noorul Hudha Hifl Madrasa | B15: Karumara Street | C15: Nellikuppam | D15: Cuddalore | E15: 607105 | F15: 9790291534,8072501209 | H15: Cuddalore | I15: 14 | J15: =COUNTIF('APPLICANTS 2023'!G:G,A15) -> 1
A16: The New John Dewey Mat High School | B16: 65/29, Kasthuribai Street | C16: Panruti | D16: Cuddalore | E16: 607106 | H16: Cuddalore | I16: 15 | J16: =COUNTIF('APPLICANTS 2023'!G:G,A16) -> 1
A17: Madrasa-E-Merajul Uloom | B17: 77/21,Mohamed Ali Club Road, Opp to BusStand | C17: Dharmapuri | D17: Dharmapuri | E17: 636701 | F17: 9786786088 | G17: zubairaafazi@gmail.com | H17: Dharmapuri | I17: 16 | J17: =COUNTIF('APPLICANTS 2023'!G:G,A17) -> 4
A18: An-Noor Islamia College | B18: Railway Station Road | C18: Thamarapadi(PO) | D18: Dindigul | E18: 624005 | F18: 8610213874 | H18: Dindigul | I18: 17 | J18: =COUNTIF('APPLICANTS 2023'!G:G,A18) -> 2
A19: Madarashathull Hamidiyah | B19: Begampur | C19: Dindigul | D19: Dindigul | E19: 624002 | F19: 9080891557 | H19: Dindigul | I19: 19 | J19: =COUNTIF('APPLICANTS 2023'!G:G,A19) -> 1
A20: Al Jamiathul Firdousiya Arabic College | B20: Parakai Road, Kottar | C20: Nagercoil | D20: Kanyakumari | E20: 629002 | F20: 9486215365,9629587691 | H20: Kanyakumari | I20: 20 | J20: =COUNTIF('APPLICANTS 2023'!G:G,A20) -> 3
A21: Al-Qalam School | B21: 25, Majestic Colony | C21: Dharmapuram | D21: Karaikal | E21: 609602 | F21: 9842158505,8300692325 | G21: alqalamschool.kkl@gmail.com | H21: Karaikal | I21: 21 | J21: =COUNTIF('APPLICANTS 2023'!G:G,A21) -> 1
A22: Madharasathul Salahiya Hiflu Madarasa | C22: T.R.Pattinam | D22: Karaikal | E22: 609606 | F22: 9750242302 | H22: Karaikal | I22: 22 | J22: =COUNTIF('APPLICANTS 2023'!G:G,A22) -> 1
A23: Ubay Ibn Ka'b Hifz Madarsa | B23: 3, Majestic Colony | C23: Dharmapuram | D23: Karaikal | E23: 609602 | F23: 75984421804,7702117140 | G23: ubayibnkabhifzmadarsa@gmail.com | H23: Karaikal | I23: 23 | J23: =COUNTIF('APPLICANTS 2023'!G:G,A23) -> 5
A24: Darul Uloom Saudia Arabic College | C24: Chinthaamanipatti (PO) | D24: Karur | E24: 621301 | F24: 9791382498 | H24: Karur | I24: 24 | J24: =COUNTIF('APPLICANTS 2023'!G:G,A24) -> 2
A25: Jamia Noman-Bin Sabith | C25: Rahmath Nagar | D25: Krishnagiri | E25: 635115 | F25: 8892288058 | G25: abdulkhadirjilani@gmail.com | H25: Krishnagiri | I25: 25 | J25: =COUNTIF('APPLICANTS 2023'!G:G,A25) -> 5
A26: Darussalam Arabic College | B26: 5, RadhaKrishnan Nagar, 5th Cross St | C26: Avaniyapuram | D26: Madurai | E26: 625012 | F26: 9443025359 | H26: Madurai | I26: 26 | J26: =COUNTIF('APPLICANTS 2023'!G:G,A26) -> 3
A27: Jannathul Firdowse Hifl Madrasa | B27: 8th street,Gomathipuram | C27: Madurai | D27: Madurai | E27: 625020 | F27: 8015335562 | H27: Madurai | I27: 27 | J27: =COUNTIF('APPLICANTS 2023'!G:G,A27) -> 3
A28: Limra Nursery & Primary School | B28: 1020,Villapuram Housing Board | C28: Madurai | D28: Madurai | E28: 625011 | F28: 9677770854,8526666344 | H28: Madurai | I28: 28 | J28: =COUNTIF('APPLICANTS 2023'!G:G,A28) -> 3
A29: Gift Islamic Academy | B29: Behind SM Oil Company | C29: Gudalur | D29: Nilgiris | E29: 643212 | F29: 9443253428 | H29: Nilgiris | I29: 29 | J29: =COUNTIF('APPLICANTS 2023'!G:G,A29) -> 6
A30: Jamia Al Asharathul Mubashara | B30: Madurai Road | C30: Endapuli | D30: Periyakulam | E30: 625604 | F30: 8110024089 | H30: Periyakulam | I30: 30 | J30: =COUNTIF('APPLICANTS 2023'!G:G,A30) -> 2
A31: Jamiathul Hiqma Arabic College | B31: Kaduvanur | C31: Bahour Commune | D31: Puducherry | E31: 607402 | F31: 04132223251,8056678315 | H31: Puducherry | I31: 31 | J31: =COUNTIF('APPLICANTS 2023'!G:G,A31) -> 1
A32: Al Munawara Islamic School | B32: Indhra Nagar, Neivasalpatty Road | C32: Sivapuram | D32: Pudukkottai | E32: 622422 | F32: 7010751922 | H32: Pudukkottai | I32: 32 | J32: =COUNTIF('APPLICANTS 2023'!G:G,A32) -> 3
A33: Bright Islamic School | B33: Vaniyar Street | C33: Karambakkudi | D33: Pudukottai | E33: 622302 | F33: 936033644,9943437338 | H33: Pudukkottai | I33: 33 | J33: =COUNTIF('APPLICANTS 2023'!G:G,A33) -> 2
A34: Nizam Oriental Arabic High School | B34: No 2, Nizam Colony | C34: Pudukkotai | D34: Pudukkottai | E34: 622001 | F34: 04322265006, 9894812904 | G34: nizamschool@yahoo.com | H34: Pudukkottai | I34: 34 | J34: =COUNTIF('APPLICANTS 2023'!G:G,A34) -> 1
A35: Syed Ibrahim Educational and Charitable Trust | B35: 3869/1, South 2nd street | C35: Pudukkotai | D35: Pudukottai | E35: 622422 | F35: 7010751922 | H35: Pudukkottai | I35: 35 | J35: =COUNTIF('APPLICANTS 2023'!G:G,A35) -> 1
A36: Al-Aqsa Quran Study Center | B36: 16, New Street | C36: Kilakarai | D36: Ramanathapuram | E36: 623517 | F36: 9566505693 | H36: Ramanathapuram | I36: 36 | J36: =COUNTIF('APPLICANTS 2023'!G:G,A36) -> 4
A37: Ayisha Hameeda Quraan Hiflu Madharasa | B37: B.S.Abdur Rahman Salai, Mulluvadi | C37: Kilakarai | D37: Ramanathapuram | E37: 623517 | F37: 9524191383,8870115468 | H37: Ramanathapuram | I37: 37 | J37: =COUNTIF('APPLICANTS 2023'!G:G,A37) -> 1
A38: Madhrasa-E-Noorul Islam Arabic College | B38: Junction, Sooramangalam P.O | C38: Salem | D38: Salem | E38: 636005 | F38: 9655071825 | H38: Salem | I38: 38 | J38: =COUNTIF('APPLICANTS 2023'!G:G,A38) -> 4
A39: Dharul Uloom Dhawathul Hudha | B39: Periyar Nagar,SBI Backside | C39: Thiruppathur | D39: Sivanganga | E39: 630211 | F39: 7708817177 | H39: Sivanganga | I39: 39 | J39: =COUNTIF('APPLICANTS 2023'!G:G,A39) -> 3
A40: Hameedia Elementary School | B40: Salaiyur | C40: Ilayangudi | D40: Sivanganga | E40: 630702 | F40: 6374835081 | H40: Sivanganga | I40: 40 | J40: =COUNTIF('APPLICANTS 2023'!G:G,A40) -> 1
...

Sheet REGISTERED
A1: REG NO | B1: NAME | C1: FATHER'S NAME | D1: I.NO | E1: INSTITUTION
A2: 505 | B2: =VLOOKUP(A2,'APPLICANTS 2023'!A:Q,2,FALSE) -> Abdullah A | C2: =VLOOKUP(A2,'APPLICANTS 2023'!A:Q,3,FALSE) -> Abubakr Amin | D2: =VLOOKUP(A2,'APPLICANTS 2023'!A:Q,6,FALSE) -> 01 | E2: =VLOOKUP(A2,'APPLICANTS 2023'!A:Q,7,FALSE) -> Bilal Madrasa For Memorizing Quran
A3: 510 | B3: =VLOOKUP(A3,'APPLICANTS 2023'!A:Q,2,FALSE) -> Afeef Ahmed | C3: =VLOOKUP(A3,'APPLICANTS 2023'!A:Q,3,FALSE) -> Mohammed Masood | D3: =VLOOKUP(A3,'APPLICANTS 2023'!A:Q,6,FALSE) -> 01 | E3: =VLOOKUP(A3,'APPLICANTS 2023'!A:Q,7,FALSE) -> Bilal Madrasa For Memorizing Quran
A4: 3012 | B4: =VLOOKUP(A4,'APPLICANTS 2023'!A:Q,2,FALSE) -> Afeef Abdullah | C4: =VLOOKUP(A4,'APPLICANTS 2023'!A:Q,3,FALSE) -> Syed Sadaqatullah | D4: =VLOOKUP(A4,'APPLICANTS 2023'!A:Q,6,FALSE) -> 01 | E4: =VLOOKUP(A4,'APPLICANTS 2023'!A:Q,7,FALSE) -> Bilal Madrasa For Memorizing Quran
A5: 3004 | B5: =VLOOKUP(A5,'APPLICANTS 2023'!A:Q,2,FALSE) -> Abdul Kaiyoom | C5: =VLOOKUP(A5,'APPLICANTS 2023'!A:Q,3,FALSE) -> Shahul Hameed | D5: =VLOOKUP(A5,'APPLICANTS 2023'!A:Q,6,FALSE) -> 01 | E5: =VLOOKUP(A5,'APPLICANTS 2023'!A:Q,7,FALSE) -> Bilal Madrasa For Memorizing Quran
A6: 3043 | B6: =VLOOKUP(A6,'APPLICANTS 2023'!A:Q,2,FALSE) -> Mohammed Kasim Ameen C.S | C6: =VLOOKUP(A6,'APPLICANTS 2023'!A:Q,3,FALSE) -> Mohammed Sadiqul Ameen | D6: =VLOOKUP(A6,'APPLICANTS 2023'!A:Q,6,FALSE) -> 02 | E6: =VLOOKUP(A6,'APPLICANTS 2023'!A:Q,7,FALSE) -> Dar-Ul-Quranul Kareem (Academy)
A7: 551 | B7: =VLOOKUP(A7,'APPLICANTS 2023'!A:Q,2,FALSE) -> Muhammadh Umar R | C7: =VLOOKUP(A7,'APPLICANTS 2023'!A:Q,3,FALSE) -> Riyaz Ahmed | D7: =VLOOKUP(A7,'APPLICANTS 2023'!A:Q,6,FALSE) -> 03 | E7: =VLOOKUP(A7,'APPLICANTS 2023'!A:Q,7,FALSE) -> Ibnu Taimiyyah Institute For Hifz & Islamic Studies With Academics (Resi)
A8: 3057 | B8: =VLOOKUP(A8,'APPLICANTS 2023'!A:Q,2,FALSE) -> Omer Abdul Caser S.M | C8: =VLOOKUP(A8,'APPLICANTS 2023'!A:Q,3,FALSE) -> Seyed Mohammed O.A.C | D8: =VLOOKUP(A8,'APPLICANTS 2023'!A:Q,6,FALSE) -> 04 | E8: =VLOOKUP(A8,'APPLICANTS 2023'!A:Q,7,FALSE) -> Kilakarai Bukhari Aalim Arabic College
A9: 1505 | B9: =VLOOKUP(A9,'APPLICANTS 2023'!A:Q,2,FALSE) -> Abdullah | C9: =VLOOKUP(A9,'APPLICANTS 2023'!A:Q,3,FALSE) -> Abdul Ghani | D9: =VLOOKUP(A9,'APPLICANTS 2023'!A:Q,6,FALSE) -> 05 | E9: =VLOOKUP(A9,'APPLICANTS 2023'!A:Q,7,FALSE) -> Madrasa Ubai Ibn Ka'b
A10: 3010 | B10: =VLOOKUP(A10,'APPLICANTS 2023'!A:Q,2,FALSE) -> Abdur Rahman | C10: =VLOOKUP(A10,'APPLICANTS 2023'!A:Q,3,FALSE) -> Abdul Ghani | D10: =VLOOKUP(A10,'APPLICANTS 2023'!A:Q,6,FALSE) -> 05 | E10: =VLOOKUP(A10,'APPLICANTS 2023'!A:Q,7,FALSE) -> Madrasa Ubai Ibn Ka'b
A11: 3009 | B11: =VLOOKUP(A11,'APPLICANTS 2023'!A:Q,2,FALSE) -> Abdullah M.S.H | C11: =VLOOKUP(A11,'APPLICANTS 2023'!A:Q,3,FALSE) -> Mohammed Seyed Hashan M.A.K | D11: =VLOOKUP(A11,'APPLICANTS 2023'!A:Q,6,FALSE) -> 06 | E11: =VLOOKUP(A11,'APPLICANTS 2023'!A:Q,7,FALSE) -> Measi Matriculation Hr Sec School
A12: 516 | B12: =VLOOKUP(A12,'APPLICANTS 2023'!A:Q,2,FALSE) -> Ammar Ali A | C12: =VLOOKUP(A12,'APPLICANTS 2023'!A:Q,3,FALSE) -> Abid Ali M.M | D12: =VLOOKUP(A12,'APPLICANTS 2023'!A:Q,6,FALSE) -> 07 | E12: =VLOOKUP(A12,'APPLICANTS 2023'!A:Q,7,FALSE) -> Sana Model School
A13: 3066 | B13: =VLOOKUP(A13,'APPLICANTS 2023'!A:Q,2,FALSE) -> Waseem Meeran S | C13: =VLOOKUP(A13,'APPLICANTS 2023'!A:Q,3,FALSE) -> Syed Jawahar Sadiq | D13: =VLOOKUP(A13,'APPLICANTS 2023'!A:Q,6,FALSE) -> 07 | E13: =VLOOKUP(A13,'APPLICANTS 2023'!A:Q,7,FALSE) -> Sana Model School
... A175: 567 | B175: =VLOOKUP(A175,'APPLICANTS 2023'!A:Q,2,FALSE) -> Mohamed Hamza | C175: =VLOOKUP(A175,'APPLICANTS 2023'!A:Q,3,FALSE) -> Mohamed Rasool | D175: =VLOOKUP(A175,'APPLICANTS 2023'!A:Q,6,FALSE) -> 77 | E175: =VLOOKUP(A175,'APPLICANTS 2023'!A:Q,7,FALSE) -> Al Jamiathul Sayidiya Quran Memorizing School (Dawathul Hudha Trust)
B176: =VLOOKUP(A176,'APPLICANTS 2023'!A:Q,2,FALSE) -> #N/A | C176: =VLOOKUP(A176,'APPLICANTS 2023'!A:Q,3,FALSE) -> #N/A | D176: =VLOOKUP(A176,'APPLICANTS 2023'!A:Q,6,FALSE) -> #N/A | E176: =VLOOKUP(A176,'APPLICANTS 2023'!A:Q,7,FALSE) -> #N/A
B177: =VLOOKUP(A177,'APPLICANTS 2023'!A:Q,2,FALSE) -> #N/A | C177: =VLOOKUP(A177,'APPLICANTS 2023'!A:Q,3,FALSE) -> #N/A | D177: =VLOOKUP(A177,'APPLICANTS 2023'!A:Q,6,FALSE) -> #N/A | E177: =VLOOKUP(A177,'APPLICANTS 2023'!A:Q,7,FALSE) -> #N/A
B178: =VLOOKUP(A178,'APPLICANTS 2023'!A:Q,2,FALSE) -> #N/A | C178: =VLOOKUP(A178,'APPLICANTS 2023'!A:Q,3,FALSE) -> #N/A | D178: =VLOOKUP(A178,'APPLICANTS 2023'!A:Q,6,FALSE) -> #N/A | E178: =VLOOKUP(A178,'APPLICANTS 2023'!A:Q,7,FALSE) -> #N/A
B179: =VLOOKUP(A179,'APPLICANTS 2023'!A:Q,2,FALSE) -> #N/A | C179: =VLOOKUP(A179,'APPLICANTS 2023'!A:Q,3,FALSE) -> #N/A | D179: =VLOOKUP(A179,'APPLICANTS 2023'!A:Q,6,FALSE) -> #N/A | E179: =VLOOKUP(A179,'APPLICANTS 2023'!A:Q,7,FALSE) -> #N/A
B180: =VLOOKUP(A180,'APPLICANTS 2023'!A:Q,2,FALSE) -> #N/A | C180: =VLOOKUP(A180,'APPLICANTS 2023'!A:Q,3,FALSE) -> #N/A | D180: =VLOOKUP(A180,'APPLICANTS 2023'!A:Q,6,FALSE) -> #N/A | E180: =VLOOKUP(A180,'APPLICANTS 2023'!A:Q,7,FALSE) -> #N/A
B181: =VLOOKUP(A181,'APPLICANTS 2023'!A:Q,2,FALSE) -> #N/A | C181: =VLOOKUP(A181,'APPLICANTS 2023'!A:Q,3,FALSE) -> #N/A | D181: =VLOOKUP(A181,'APPLICANTS 2023'!A:Q,6,FALSE) -> #N/A | E181: =VLOOKUP(A181,'APPLICANTS 2023'!A:Q,7,FALSE) -> #N/A
B182: =VLOOKUP(A182,'APPLICANTS 2023'!A:Q,2,FALSE) -> #N/A | C182: =VLOOKUP(A182,'APPLICANTS 2023'!A:Q,3,FALSE) -> #N/A | D182: =VLOOKUP(A182,'APPLICANTS 2023'!A:Q,6,FALSE) -> #N/A | E182: =VLOOKUP(A182,'APPLICANTS 2023'!A:Q,7,FALSE) -> #N/A

Sheet MARKS
A1: REG NO | B1: STAGE | C1: J1 - HIFZ-1 | D1: J1 - HIFZ-2 | E1: J1 - TAJ -1 | F1: J1 - TAJ -2 | G1: J1 - ISMU -1 | H1: J1 - ISMU -2 | I1: J1 - MUTH -1 | J1: J1 - MUTH -2 | K1: J1 - MUTH -3 | L1: J2 - HIFZ-1 | M1: J2 - HIFZ-2 | N1: J2 - TAJ -1 | O1: J2 - TAJ -2 | P1: J2 - ISMU -1 | Q1: J2 - ISMU -2 | R1: J2 - MUTH -1 | S1: J2 - MUTH -2 | T1: J2 - MUTH -3 | U1: TOTAL | V1: NAME | W1: FATHER'S NAME | X1: I.NO | Y1: I. Name | Z1: TOWN
A2: 3030 | B2: B | C2: 20 | D2: 0 | E2: 5 | F2: 7 | G2: 0 | H2: 5 | I2: 0 | J2: 0 | K2: 0 | L2: 20 | M2: 5 | N2: 6 | O2: 3 | P2: 0 | Q2: 0 | R2: 0 | S2: 0 | T2: 0 | U2: =SUM(C2:T2) -> 71 | V2: =VLOOKUP(A2,'APPLICANTS 2023'!A:Q,2,FALSE) -> Mohamed Hasan S | W2: =VLOOKUP(A2,'APPLICANTS 2023'!A:Q,3,FALSE) -> Sowgath Ali | X2: =VLOOKUP(A2,'APPLICANTS 2023'!A:Q,6,FALSE) -> 26 | Y2: =VLOOKUP(A2,'APPLICANTS 2023'!A:Q,7,FALSE) -> Darussalam Arabic College | Z2: =VLOOKUP(A2,'APPLICANTS 2023'!A:Q,9,FALSE) -> Avaniyapuram
A3: 3007 | B3: B | C3: 18 | D3: 10 | E3: 7 | F3: 4 | G3: 5 | H3: 5 | I3: 10 | J3: 7 | K3: 0 | L3: 20 | M3: 0 | N3: 8 | O3: 8 | P3: 5 | Q3: 5 | R3: 10 | S3: 10 | T3: 0 | U3: =SUM(C3:T3) -> 132 | V3: =VLOOKUP(A3,'APPLICANTS 2023'!A:Q,2,FALSE) -> Abdullah A.R | W3: =VLOOKUP(A3,'APPLICANTS 2023'!A:Q,3,FALSE) -> Abdul Rahim M.H | X3: =VLOOKUP(A3,'APPLICANTS 2023'!A:Q,6,FALSE) -> 57 | Y3: =VLOOKUP(A3,'APPLICANTS 2023'!A:Q,7,FALSE) -> Al Makthabathul Magudhoomiyya | Z3: =VLOOKUP(A3,'APPLICANTS 2023'!A:Q,9,FALSE) -> Kayalpatnam
A4: 3020 | B4: B | C4: 20 | D4: 20 | E4: 9 | F4: 8 | G4: 5 | H4: 5 | I4: 10 | J4: 8 | K4: 0 | L4: 20 | M4: 20 | N4: 9 | O4: 9 | P4: 5 | Q4: 5 | R4: 10 | S4: 7 | T4: 0 | U4: =SUM(C4:T4) -> 170 | V4: =VLOOKUP(A4,'APPLICANTS 2023'!A:Q,2,FALSE) -> Dasthageer K.M | W4: =VLOOKUP(A4,'APPLICANTS 2023'!A:Q,3,FALSE) -> Ismail K.M | X4: =VLOOKUP(A4,'APPLICANTS 2023'!A:Q,6,FALSE) -> 72 | Y4: =VLOOKUP(A4,'APPLICANTS 2023'!A:Q,7,FALSE) -> Madrasa E Imdadiya For The Blind | Z4: =VLOOKUP(A4,'APPLICANTS 2023'!A:Q,9,FALSE) -> Melvisharam
A5: 3015 | B5: B | C5: 0 | D5: 0 | E5: 0 | F5: 0 | G5: 0 | H5: 0 | I5: 0 | J5: 0 | K5: 0 | L5: 0 | M5: 0 | N5: 0 | O5: 0 | P5: 0 | Q5: 0 | R5: 0 | S5: 0 | T5: 0 | U5: =SUM(C5:T5) -> 0 | V5: =VLOOKUP(A5,'APPLICANTS 2023'!A:Q,2,FALSE) -> Ahamed Ibrahim R | W5: =VLOOKUP(A5,'APPLICANTS 2023'!A:Q,3,FALSE) -> Rafeek MuhamedMusthafa | X5: =VLOOKUP(A5,'APPLICANTS 2023'!A:Q,6,FALSE) -> 63 | Y5: =VLOOKUP(A5,'APPLICANTS 2023'!A:Q,7,FALSE) -> SFTC Tutorial & Tution Centre | Z5: =VLOOKUP(A5,'APPLICANTS 2023'!A:Q,9,FALSE) -> Kayalpatnam
A6: 3038 | B6: B | C6: 0 | D6: 0 | E6: 0 | F6: 0 | G6: 0 | H6: 0 | I6: 0 | J6: 0 | K6: 0 | L6: 2 | M6: 0 | N6: 0 | O6: 0 | P6: 0 | Q6: 0 | R6: 0 | S6: 0 | T6: 0 | U6: =SUM(C6:T6) -> 2 | V6: =VLOOKUP(A6,'APPLICANTS 2023'!A:Q,2,FALSE) -> Mohamed Shehin S | W6: =VLOOKUP(A6,'APPLICANTS 2023'!A:Q,3,FALSE) -> Saidalavi | X6: =VLOOKUP(A6,'APPLICANTS 2023'!A:Q,6,FALSE) -> 29 | Y6: =VLOOKUP(A6,'APPLICANTS 2023'!A:Q,7,FALSE) -> Gift Islamic Academy | Z6: =VLOOKUP(A6,'APPLICANTS 2023'!A:Q,9,FALSE) -> Gudalur
A7: 3061 | B7: A | C7: 0 | D7: 7 | E7: 3 | F7: 3 | G7: 3 | H7: 3 | I7: 9 | J7: 9 | K7: 9 | L7: 8 | M7: 15 | N7: 5 | O7: 5 | P7: 4 | Q7: 4 | R7: 8 | S7: 8 | T7: 10 | U7: =SUM(C7:T7) -> 113 | V7: =VLOOKUP(A7,'APPLICANTS 2023'!A:Q,2,FALSE) -> Seyed Omer A | W7: =VLOOKUP(A7,'APPLICANTS 2023'!A:Q,3,FALSE) -> Abdullah S.O | X7: =VLOOKUP(A7,'APPLICANTS 2023'!A:Q,6,FALSE) -> 57 | Y7: =VLOOKUP(A7,'APPLICANTS 2023'!A:Q,7,FALSE) -> Al Makthabathul Magudhoomiyya | Z7: =VLOOKUP(A7,'APPLICANTS 2023'!A:Q,9,FALSE) -> Kayalpatnam
A8: 3045 | B8: A | C8: 19 | D8: 19 | E8: 8 | F8: 10 | G8: 5 | H8: 5 | I8: 10 | J8: 10 | K8: 10 | L8: 20 | M8: 18 | N8: 8 | O8: 8 | P8: 5 | Q8: 5 | R8: 10 | S8: 10 | T8: 10 | U8: =SUM(C8:T8) -> 190 | V8: =VLOOKUP(A8,'APPLICANTS 2023'!A:Q,2,FALSE) -> Mohammed Talha | W8: =VLOOKUP(A8,'APPLICANTS 2023'!A:Q,3,FALSE) -> Majeed Pasha | X8: =VLOOKUP(A8,'APPLICANTS 2023'!A:Q,6,FALSE) -> 73 | Y8: =VLOOKUP(A8,'APPLICANTS 2023'!A:Q,7,FALSE) -> Madrasa E Imdadul Uloom | Z8: =VLOOKUP(A8,'APPLICANTS 2023'!A:Q,9,FALSE) -> Pernambut
A9: 3027 | B9: A | C9: 10 | D9: 8 | E9: 7 | F9: 6 | G9: 4 | H9: 5 | I9: 8 | J9: 7 | K9: 0 | L9: 3 | M9: 7 | N9: 2 | O9: 2 | P9: 1 | Q9: 2 | R9: 2 | S9: 2 | T9: 0 | U9: =SUM(C9:T9) -> 76 | V9: =VLOOKUP(A9,'APPLICANTS 2023'!A:Q,2,FALSE) -> Mohamed Aslam R | W9: =VLOOKUP(A9,'APPLICANTS 2023'!A:Q,3,FALSE) -> Raja Mohamed | X9: =VLOOKUP(A9,'APPLICANTS 2023'!A:Q,6,FALSE) -> 56 | Y9: =VLOOKUP(A9,'APPLICANTS 2023'!A:Q,7,FALSE) -> Al Mahir Quran Memorizing School | Z9: =VLOOKUP(A9,'APPLICANTS 2023'!A:Q,9,FALSE) -> Kayalpatnam
A10: 3064 | B10: A | C10: 0 | D10: 0 | E10: 0 | F10: 0 | G10: 0 | H10: 0 | I10: 0 | J10: 0 | K10: 0 | L10: 0 | M10: 0 | N10: 0 | O10: 0 | P10: 0 | Q10: 0 | R10: 0 | S10: 0 | T10: 0 | U10: =SUM(C10:T10) -> 0 | V10: =VLOOKUP(A10,'APPLICANTS 2023'!A:Q,2,FALSE) -> Syed Hasan S.S | W10: =VLOOKUP(A10,'APPLICANTS 2023'!A:Q,3,FALSE) -> Syed Sajjath H | X10: =VLOOKUP(A10,'APPLICANTS 2023'!A:Q,6,FALSE) -> 29 | Y10: =VLOOKUP(A10,'APPLICANTS 2023'!A:Q,7,FALSE) -> Gift Islamic Academy | Z10: =VLOOKUP(A10,'APPLICANTS 2023'!A:Q,9,FALSE) -> Gudalur
A11: 3010 | B11: A | C11: 20 | D11: 15 | E11: 10 | F11: 10 | G11: 5 | H11: 5 | I11: 10 | J11: 0 | K11: 0 | L11: 18 | M11: 16 | N11: 8 | O11: 9 | P11: 5 | Q11: 5 | R11: 8 | S11: 5 | T11: 5 | U11: =SUM(C11:T11) -> 154 | V11: =VLOOKUP(A11,'APPLICANTS 2023'!A:Q,2,FALSE) -> Abdur Rahman | W11: =VLOOKUP(A11,'APPLICANTS 2023'!A:Q,3,FALSE) -> Abdul Ghani | X11: =VLOOKUP(A11,'APPLICANTS 2023'!A:Q,6,FALSE) -> 05 | Y11: =VLOOKUP(A11,'APPLICANTS 2023'!A:Q,7,FALSE) -> Madrasa Ubai Ibn Ka'b | Z11: =VLOOKUP(A11,'APPLICANTS 2023'!A:Q,9,FALSE) -> Chennai
A12: 3056 | B12: A | C12: 16 | D12: 10 | E12: 5 | F12: 5 | G12: 3 | H12: 3 | I12: 0 | J12: 0 | K12: 0 | L12: 18 | M12: 19 | N12: 8 | O12: 9 | P12: 5 | Q12: 5 | R12: 8 | S12: 0 | T12: 0 | U12: =SUM(C12:T12) -> 114 | V12: =VLOOKUP(A12,'APPLICANTS 2023'!A:Q,2,FALSE) -> Nihaal M | W12: =VLOOKUP(A12,'APPLICANTS 2023'!A:Q,3,FALSE) -> Mohammed Haneefa | X12: =VLOOKUP(A12,'APPLICANTS 2023'!A:Q,6,FALSE) -> 12 | Y12: =VLOOKUP(A12,'APPLICANTS 2023'!A:Q,7,FALSE) -> Pristine Public School | Z12: =VLOOKUP(A12,'APPLICANTS 2023'!A:Q,9,FALSE) -> Coimbatore
A13: 1524 | B13: C | C13: 8 | D13: 8 | E13: 6 | F13: 6 | G13: 5 | H13: 0 | I13: 2 | J13: 2 | K13: 2 | L13: 8 | M13: 8 | N13: 5 | O13: 5 | P13: 0 | Q13: 0 | R13: 3 | S13: 3 | T13: 3 | U13: =SUM(C13:T13) -> 74 | V13: =VLOOKUP(A13,'APPLICANTS 2023'!A:Q,2,FALSE) -> Mohamed Munaf | W13: =VLOOKUP(A13,'APPLICANTS 2023'!A:Q,3,FALSE) -> Dulfikar Hasan | X13: =VLOOKUP(A13,'APPLICANTS 2023'!A:Q,6,FALSE) -> 36 | Y13: =VLOOKUP(A13,'APPLICANTS 2023'!A:Q,7,FALSE) -> Al-Aqsa Quran Study Center | Z13: =VLOOKUP(A13,'APPLICANTS 2023'!A:Q,9,FALSE) -> Kilakarai
... A76: 1540 | B76: C | C76: 17 | D76: 0 | E76: 7 | F76: 0 | G76: 5 | H76: 0 | I76: 0 | J76: 8 | K76: 0 | L76: 14 | M76: 0 | N76: 4 | O76: 0 | P76: 5 | Q76: 0 | R76: 8 | S76: 0 | T76: 0 | U76: =SUM(C76:T76) -> 68 | V76: =VLOOKUP(A76,'APPLICANTS 2023'!A:Q,2,FALSE) -> Nijardeen T | W76: =VLOOKUP(A76,'APPLICANTS 2023'!A:Q,3,FALSE) -> Tajdeen | X76: =VLOOKUP(A76,'APPLICANTS 2023'!A:Q,6,FALSE) -> 33 | Y76: =VLOOKUP(A76,'APPLICANTS 2023'!A:Q,7,FALSE) -> Bright Islamic School | Z76: =VLOOKUP(A76,'APPLICANTS 2023'!A:Q,9,FALSE) -> Karambakkudi
A77: 1520 | B77: C | C77: 20 | D77: 16 | E77: 7 | F77: 8 | G77: 5 | H77: 5 | I77: 10 | J77: 0 | K77: 0 | L77: 2 | M77: 16 | O77: 7 | P77: 5 | Q77: 5 | R77: 10 | S77: 0 | T77: 0 | U77: =SUM(C77:T77) -> 116 | V77: =VLOOKUP(A77,'APPLICANTS 2023'!A:Q,2,FALSE) -> Jumail Ahmed | W77: =VLOOKUP(A77,'APPLICANTS 2023'!A:Q,3,FALSE) -> Mohammed Rafeek K | X77: =VLOOKUP(A77,'APPLICANTS 2023'!A:Q,6,FALSE) -> 45 | Y77: =VLOOKUP(A77,'APPLICANTS 2023'!A:Q,7,FALSE) -> Al Jamiyathul Islamiya | Z77: =VLOOKUP(A77,'APPLICANTS 2023'!A:Q,9,FALSE) -> Ayyampet
A78: 3057 | B78: A | C78: 8 | D78: 3 | E78: 2 | F78: 2 | G78: 1 | H78: 1 | I78: 0 | J78: 0 | K78: 0 | L78: 16 | M78: 17 | N78: 8 | O78: 4 | P78: 5 | Q78: 5 | R78: 8 | S78: 0 | T78: 0 | U78: =SUM(C78:T78) -> 80 | V78: =VLOOKUP(A78,'APPLICANTS 2023'!A:Q,2,FALSE) -> Omer Abdul Caser S.M | W78: =VLOOKUP(A78,'APPLICANTS 2023'!A:Q,3,FALSE) -> Seyed Mohammed O.A.C | X78: =VLOOKUP(A78,'APPLICANTS 2023'!A:Q,6,FALSE) -> 04 | Y78: =VLOOKUP(A78,'APPLICANTS 2023'!A:Q,7,FALSE) -> Kilakarai Bukhari Aalim Arabic College | Z78: =VLOOKUP(A78,'APPLICANTS 2023'!A:Q,9,FALSE) -> Chennai
A79: 3009 | B79: A | C79: 20 | D79: 20 | E79: 9 | F79: 9 | G79: 5 | H79: 3 | I79: 10 | J79: 7 | K79: 0 | L79: 20 | M79: 20 | N79: 9 | O79: 10 | P79: 0 | Q79: 5 | R79: 10 | S79: 8 | T79: 8 | U79: =SUM(C79:T79) -> 173 | V79: =VLOOKUP(A79,'APPLICANTS 2023'!A:Q,2,FALSE) -> Abdullah M.S.H | W79: =VLOOKUP(A79,'APPLICANTS 2023'!A:Q,3,FALSE) -> Mohammed Seyed Hashan M.A.K | X79: =VLOOKUP(A79,'APPLICANTS 2023'!A:Q,6,FALSE) -> 06 | Y79: =VLOOKUP(A79,'APPLICANTS 2023'!A:Q,7,FALSE) -> Measi Matriculation Hr Sec School | Z79: =VLOOKUP(A79,'APPLICANTS 2023'!A:Q,9,FALSE) -> Chennai
A80: 527 | B80: D | C80: 20 | D80: 20 | E80: 6 | F80: 10 | G80: 5 | H80: 5 | I80: 10 | J80: 15 | K80: 0 | L80: 15 | M80: 20 | N80: 8 | O80: 7 | P80: 5 | Q80: 5 | R80: 15 | S80: 15 | T80: 0 | U80: =SUM(C80:T80) -> 181 | V80: =VLOOKUP(A80,'APPLICANTS 2023'!A:Q,2,FALSE) -> Mohamed Ibrahim T.S.M | W80: =VLOOKUP(A80,'APPLICANTS 2023'!A:Q,3,FALSE) -> Mohamed Eassa T.A.S | X80: =VLOOKUP(A80,'APPLICANTS 2023'!A:Q,6,FALSE) -> 27 | Y80: =VLOOKUP(A80,'APPLICANTS 2023'!A:Q,7,FALSE) -> Jannathul Firdowse Hifl Madrasa | Z80: =VLOOKUP(A80,'APPLICANTS 2023'!A:Q,9,FALSE) -> Madurai
A81: 542 | B81: D | C81: 15 | D81: 10 | E81: 6 | F81: 5 | G81: 5 | H81: 0 | I81: 9 | J81: 5 | K81: 0 | L81: 15 | M81: 5 | N81: 6 | O81: 5 | P81: 5 | Q81: 0 | R81: 15 | S81: 12 | T81: 0 | U81: =SUM(C81:T81) -> 118 | V81: =VLOOKUP(A81,'APPLICANTS 2023'!A:Q,2,FALSE) -> Mohammed Moin | W81: =VLOOKUP(A81,'APPLICANTS 2023'!A:Q,3,FALSE) -> Mohammed Murshid | X81: =VLOOKUP(A81,'APPLICANTS 2023'!A:Q,6,FALSE) -> 16 | Y81: =VLOOKUP(A81,'APPLICANTS 2023'!A:Q,7,FALSE) -> Madrasa-E-Merajul Uloom | Z81: =VLOOKUP(A81,'APPLICANTS 2023'!A:Q,9,FALSE) -> Dharmapuri
A82: 503 | B82: D | C82: 15 | D82: 18 | E82: 6 | F82: 5 | G82: 5 | H82: 5 | I82: 12 | J82: 11 | K82: 0 | L82: 15 | M82: 17 | N82: 5 | O82: 5 | P82: 5 | Q82: 5 | R82: 10 | S82: 15 | T82: 0 | U82: =SUM(C82:T82) -> 154 | V82: =VLOOKUP(A82,'APPLICANTS 2023'!A:Q,2,FALSE) -> Abdul Kaathir J.M | W82: =VLOOKUP(A82,'APPLICANTS 2023'!A:Q,3,FALSE) -> Jamal Mohamed A.K | X82: =VLOOKUP(A82,'APPLICANTS 2023'!A:Q,6,FALSE) -> 58 | Y82: =VLOOKUP(A82,'APPLICANTS 2023'!A:Q,7,FALSE) -> L.K.Higher Secondary School | Z82: =VLOOKUP(A82,'APPLICANTS 2023'!A:Q,9,FALSE) -> Kayalpatnam
A83: 504 | B83: D | C83: 13 | D83: 12 | E83: 7 | F83: 5 | G83: 5 | H83: 5 | I83: 12 | J83: 15 | K83: 0 | L83: 15 | M83: 13 | N83: 9 | O83: 12 | P83: 5 | Q83: 5 | R83: 10 | S83: 10 | T83: 0 | U83: =SUM(C83:T83) -> 153 | V83: =VLOOKUP(A83,'APPLICANTS 2023'!A:Q,2,FALSE) -> Abdullah A | W83: =VLOOKUP(A83,'APPLICANTS 2023'!A:Q,3,FALSE) -> Abdul Nazer V.M | X83: =VLOOKUP(A83,'APPLICANTS 2023'!A:Q,6,FALSE) -> 29 | Y83: =VLOOKUP(A83,'APPLICANTS 2023'!A:Q,7,FALSE) -> Gift Islamic Academy | Z83: =VLOOKUP(A83,'APPLICANTS 2023'!A:Q,9,FALSE) -> Gudalur
A84: 532 | B84: D | C84: 10 | D84: 10 | E84: 5 | F84: 9 | G84: 5 | H84: 5 | I84: 15 | J84: 15 | K84: 0 | L84: 8 | M84: 13 | N84: 7 | O84: 7 | P84: 5 | Q84: 5 | R84: 15 | S84: 15 | T84: 0 | U84: =SUM(C84:T84) -> 149 | V84: =VLOOKUP(A84,'APPLICANTS 2023'!A:Q,2,FALSE) -> Mohamed Tanzeem I | W84: =VLOOKUP(A84,'APPLICANTS 2023'!A:Q,3,FALSE) -> Ifthihar Rahman | X84: =VLOOKUP(A84,'APPLICANTS 2023'!A:Q,6,FALSE) -> 32 | Y84: =VLOOKUP(A84,'APPLICANTS 2023'!A:Q,7,FALSE) -> Al Munawara Islamic School | Z84: =VLOOKUP(A84,'APPLICANTS 2023'!A:Q,9,FALSE) -> Sivapuram
A85: 512 | B85: E | C85: 15 | D85: 0 | E85: 10 | F85: 6 | G85: 5 | H85: 5 | I85: 10 | J85: 0 | K85: 0 | L85: 15 | M85: 10 | N85: 5 | O85: 6 | P85: 5 | Q85: 5 | R85: 10 | S85: 0 | T85: 0 | U85: =SUM(C85:T85) -> 107 | V85: =VLOOKUP(A85,'APPLICANTS 2023'!A:Q,2,FALSE) -> Ahnaf T.A | W85: =VLOOKUP(A85,'APPLICANTS 2023'!A:Q,3,FALSE) -> Thameem Ansari T | X85: =VLOOKUP(A85,'APPLICANTS 2023'!A:Q,6,FALSE) -> 60 | Y85: =VLOOKUP(A85,'APPLICANTS 2023'!A:Q,7,FALSE) -> Madarasathul Azhar Li Thahfeezil Quranil Kareem | Z85: =VLOOKUP(A85,'APPLICANTS 2023'!A:Q,9,FALSE) -> Kayalpatnam
A86: 529 | B86: E | C86: 20 | D86: 15 | E86: 10 | F86: 10 | G86: 5 | H86: 5 | I86: 15 | J86: 15 | K86: 0 | L86: 20 | M86: 18 | N86: 10 | O86: 10 | P86: 5 | Q86: 5 | R86: 15 | S86: 15 | T86: 0 | U86: =SUM(C86:T86) -> 193 | V86: =VLOOKUP(A86,'APPLICANTS 2023'!A:Q,2,FALSE) -> Mohamed Mubid | W86: =VLOOKUP(A86,'APPLICANTS 2023'!A:Q,3,FALSE) -> Ameer John | X86: =VLOOKUP(A86,'APPLICANTS 2023'!A:Q,6,FALSE) -> 40 | Y86: =VLOOKUP(A86,'APPLICANTS 2023'!A:Q,7,FALSE) -> Hameedia Elementary School | Z86: =VLOOKUP(A86,'APPLICANTS 2023'!A:Q,9,FALSE) -> Ilayangudi
A87: 555 | B87: E | C87: 15 | D87: 12 | E87: 8 | F87: 8 | G87: 5 | H87: 5 | I87: 15 | J87: 15 | K87: 0 | L87: 5 | M87: 5 | N87: 8 | O87: 8 | P87: 5 | Q87: 5 | R87: 15 | S87: 15 | T87: 0 | U87: =SUM(C87:T87) -> 149 | V87: =VLOOKUP(A87,'APPLICANTS 2023'!A:Q,2,FALSE) -> Rayyaan H | W87: =VLOOKUP(A87,'APPLICANTS 2023'!A:Q,3,FALSE) -> Haja Mohaitheen | X87: =VLOOKUP(A87,'APPLICANTS 2023'!A:Q,6,FALSE) -> 56 | Y87: =VLOOKUP(A87,'APPLICANTS 2023'!A:Q,7,FALSE) -> Al Mahir Quran Memorizing School | Z87: =VLOOKUP(A87,'APPLICANTS 2023'!A:Q,9,FALSE) -> Kayalpatnam
A88: 521 | B88: E | C88: 5 | D88: 15 | E88: 10 | F88: 10 | G88: 5 | H88: 5 | I88: 12.5 | J88: 13 | K88: 0 | L88: 15 | M88: 15 | N88: 8 | O88: 8 | P88: 5 | Q88: 5 | R88: 8 | S88: 8 | T88: 0 | U88: =SUM(C88:T88) -> 147.5 | V88: =VLOOKUP(A88,'APPLICANTS 2023'!A:Q,2,FALSE) -> Farzeen | W88: =VLOOKUP(A88,'APPLICANTS 2023'!A:Q,3,FALSE) -> Hasan Fareed | X88: =VLOOKUP(A88,'APPLICANTS 2023'!A:Q,6,FALSE) -> 36 | Y88: =VLOOKUP(A88,'APPLICANTS 2023'!A:Q,7,FALSE) -> Al-Aqsa Quran Study Center | Z88: =VLOOKUP(A88,'APPLICANTS 2023'!A:Q,9,FALSE) -> Kilakarai
A89: 536 | B89: E | C89: 15 | D89: 20 | E89: 8 | F89: 8 | G89: 0 | H89: 0 | I89: 8 | J89: 8 | K89: 0 | L89: 5 | M89: 10 | N89: 10 | O89: 10 | P89: 0 | Q89: 0 | R89: 10 | S89: 15 | T89: 0 | U89: =SUM(C89:T89) -> 127 | V89: =VLOOKUP(A89,'APPLICANTS 2023'!A:Q,2,FALSE) -> Mohammed Ali R | W89: =VLOOKUP(A89,'APPLICANTS 2023'!A:Q,3,FALSE) -> Raja Hussain | X89: =VLOOKUP(A89,'APPLICANTS 2023'!A:Q,6,FALSE) -> 27 | Y89: =VLOOKUP(A89,'APPLICANTS 2023'!A:Q,7,FALSE) -> Jannathul Firdowse Hifl Madrasa | Z89: =VLOOKUP(A89,'APPLICANTS 2023'!A:Q,9,FALSE) -> Madurai
... A175: 1536 | B175: C | C175: 16 | D175: 10 | E175: 6 | F175: 4 | G175: 5 | H175: 5 | I175: 6 | J175: 10 | K175: 10 | L175: 16 | M175: 10 | N175: 8 | O175: 8 | P175: 5 | Q175: 5 | R175: 8 | S175: 10 | T175: 10 | U175: =SUM(C175:T175) -> 152 | V175: =VLOOKUP(A175,'APPLICANTS 2023'!A:Q,2,FALSE) -> Muhammad Faahim | W175: =VLOOKUP(A175,'APPLICANTS 2023'!A:Q,3,FALSE) -> Maashukur Rahman | X175: =VLOOKUP(A175,'APPLICANTS 2023'!A:Q,6,FALSE) -> 32 | Y175: =VLOOKUP(A175,'APPLICANTS 2023'!A:Q,7,FALSE) -> Al Munawara Islamic School | Z175: =VLOOKUP(A175,'APPLICANTS 2023'!A:Q,9,FALSE) -> Sivapuram
U176: =SUM(C176:T176) -> 0 | V176: =VLOOKUP(A176,'APPLICANTS 2023'!A:Q,2,FALSE) -> #N/A | W176: =VLOOKUP(A176,'APPLICANTS 2023'!A:Q,3,FALSE) -> #N/A | X176: =VLOOKUP(A176,'APPLICANTS 2023'!A:Q,6,FALSE) -> #N/A | Y176: =VLOOKUP(A176,'APPLICANTS 2023'!A:Q,7,FALSE) -> #N/A | Z176: =VLOOKUP(A176,'APPLICANTS 2023'!A:Q,9,FALSE) -> #N/A
U177: =SUM(C177:T177) -> 0 | V177: =VLOOKUP(A177,'APPLICANTS 2023'!A:Q,2,FALSE) -> #N/A | W177: =VLOOKUP(A177,'APPLICANTS 2023'!A:Q,3,FALSE) -> #N/A | X177: =VLOOKUP(A177,'APPLICANTS 2023'!A:Q,6,FALSE) -> #N/A | Y177: =VLOOKUP(A177,'APPLICANTS 2023'!A:Q,7,FALSE) -> #N/A | Z177: =VLOOKUP(A177,'APPLICANTS 2023'!A:Q,9,FALSE) -> #N/A
U178: =SUM(C178:T178) -> 0 | V178: =VLOOKUP(A178,'APPLICANTS 2023'!A:Q,2,FALSE) -> #N/A | W178: =VLOOKUP(A178,'APPLICANTS 2023'!A:Q,3,FALSE) -> #N/A | X178: =VLOOKUP(A178,'APPLICANTS 2023'!A:Q,6,FALSE) -> #N/A | Y178: =VLOOKUP(A178,'APPLICANTS 2023'!A:Q,7,FALSE) -> #N/A | Z178: =VLOOKUP(A178,'APPLICANTS 2023'!A:Q,9,FALSE) -> #N/A
U179: =SUM(C179:T179) -> 0 | V179: =VLOOKUP(A179,'APPLICANTS 2023'!A:Q,2,FALSE) -> #N/A | W179: =VLOOKUP(A179,'APPLICANTS 2023'!A:Q,3,FALSE) -> #N/A | X179: =VLOOKUP(A179,'APPLICANTS 2023'!A:Q,6,FALSE) -> #N/A | Y179: =VLOOKUP(A179,'APPLICANTS 2023'!A:Q,7,FALSE) -> #N/A | Z179: =VLOOKUP(A179,'APPLICANTS 2023'!A:Q,9,FALSE) -> #N/A
U180: =SUM(C180:T180) -> 0 | V180: =VLOOKUP(A180,'APPLICANTS 2023'!A:Q,2,FALSE) -> #N/A | W180: =VLOOKUP(A180,'APPLICANTS 2023'!A:Q,3,FALSE) -> #N/A | X180: =VLOOKUP(A180,'APPLICANTS 2023'!A:Q,6,FALSE) -> #N/A | Y180: =VLOOKUP(A180,'APPLICANTS 2023'!A:Q,7,FALSE) -> #N/A | Z180: =VLOOKUP(A180,'APPLICANTS 2023'!A:Q,9,FALSE) -> #N/A
U181: =SUM(C181:T181) -> 0 | V181: =VLOOKUP(A181,'APPLICANTS 2023'!A:Q,2,FALSE) -> #N/A | W181: =VLOOKUP(A181,'APPLICANTS 2023'!A:Q,3,FALSE) -> #N/A | X181: =VLOOKUP(A181,'APPLICANTS 2023'!A:Q,6,FALSE) -> #N/A | Y181: =VLOOKUP(A181,'APPLICANTS 2023'!A:Q,7,FALSE) -> #N/A | Z181: =VLOOKUP(A181,'APPLICANTS 2023'!A:Q,9,FALSE) -> #N/A
U182: =SUM(C182:T182) -> 0 | V182: =VLOOKUP(A182,'APPLICANTS 2023'!A:Q,2,FALSE) -> #N/A | W182: =VLOOKUP(A182,'APPLICANTS 2023'!A:Q,3,FALSE) -> #N/A | X182: =VLOOKUP(A182,'APPLICANTS 2023'!A:Q,6,FALSE) -> #N/A | Y182: =VLOOKUP(A182,'APPLICANTS 2023'!A:Q,7,FALSE) -> #N/A | Z182: =VLOOKUP(A182,'APPLICANTS 2023'!A:Q,9,FALSE) -> #N/A

Sheet MARKS FINAL
A1: REG NO | B1: STAGE | C1: J1 - HIFZ-1 | D1: J1 - TAJ -1 | E1: J1 - ISMU -1 | F1: J1 - MUTH -11 | G1: J1 - MUTH -12 | H1: J1 - MUTH -13 | I1: J1 - MUTH -14 | J1: J1 - MUTH -21 | K1: J1 - MUTH -22 | L1: J1 - MUTH -23 | M1: J1 - MUTH -24 | N1: J2 - HIFZ-1 | O1: J2 - TAJ -1 | P1: J2 - ISMU -1 | Q1: J2 - MUTH -11 | R1: J2 - MUTH -12 | S1: J2 - MUTH -13 | T1: J2 - MUTH -14 | U1: J2 - MUTH -21 | V1: J2 - MUTH -22 | W1: J2 - MUTH -23 | X1: J2 - MUTH -24 | Y1: J3 - HIFZ-1 | Z1: J3 - TAJ -1 | AA1: J3 - ISMU -1 | AB1: J3 - MUTH -11 | AC1: J3 - MUTH -12 | AD1: J3 - MUTH -13 | AE1: J3 - MUTH -14 | AF1: J3 - MUTH -21 | AG1: J3 - MUTH -22 | AH1: J3 - MUTH -23 | AI1: J3 - MUTH -24 | AJ1: TOTAL | AK1: NAME | AL1: FATHER'S NAME | AM1: I.NO | AN1: I. Name | AO1: TOWN
A2: 557 | B2: 5 | C2: 25 | D2: 7 | E2: 5 | F2: 10 | G2: 0 | H2: 0 | I2: 0 | J2: 10 | K2: 10 | L2: 8 | M2: 0 | N2: 25 | O2: 10 | P2: 5 | Q2: 10 | R2: 0 | S2: 0 | T2: 0 | U2: 10 | V2: 10 | W2: 10 | X2: 0 | Y2: 25 | Z2: 7 | AA2: 5 | AB2: 10 | AC2: 0 | AD2: 0 | AE2: 0 | AF2: 10 | AG2: 10 | AH2: 10 | AI2: 0 | AJ2: =SUM(C2:AI2) -> 232 | AK2: =VLOOKUP(A2,'APPLICANTS 2023'!A:Q,2,FALSE) -> Sadhu Hamthan | AL2: =VLOOKUP(A2,'APPLICANTS 2023'!A:Q,3,FALSE) -> Omar Abdullah | AM2: =VLOOKUP(A2,'APPLICANTS 2023'!A:Q,6,FALSE) -> 23 | AN2: =VLOOKUP(A2,'APPLICANTS 2023'!A:Q,7,FALSE) -> Ubay Ibn Ka'b Hifz Madarsa | AO2: =VLOOKUP(A2,'APPLICANTS 2023'!A:Q,9,FALSE) -> Dharmapuram
A3: 507 | B3: 5 | C3: 25 | D3: 8 | E3: 5 | F3: 8 | G3: 10 | H3: 0 | I3: 0 | J3: 10 | K3: 10 | L3: 7 | M3: 0 | N3: 25 | O3: 9 | P3: 5 | Q3: 10 | R3: 10 | S3: 0 | T3: 0 | U3: 10 | V3: 10 | W3: 10 | X3: 0 | Y3: 24 | Z3: 8 | AA3: 5 | AB3: 8 | AC3: 10 | AD3: 0 | AE3: 0 | AF3: 10 | AG3: 8 | AH3: 10 | AI3: 0 | AJ3: =SUM(C3:AI3) -> 255 | AK3: =VLOOKUP(A3,'APPLICANTS 2023'!A:Q,2,FALSE) -> Abdur Rahman N | AL3: =VLOOKUP(A3,'APPLICANTS 2023'!A:Q,3,FALSE) -> Nizar Hussain A | AM3: =VLOOKUP(A3,'APPLICANTS 2023'!A:Q,6,FALSE) -> 20 | AN3: =VLOOKUP(A3,'APPLICANTS 2023'!A:Q,7,FALSE) -> Al Jamiathul Firdousiya Arabic College | AO3: =VLOOKUP(A3,'APPLICANTS 2023'!A:Q,9,FALSE) -> Nagercoil
A4: 565 | B4: 5 | C4: 22 | D4: 7 | E4: 5 | F4: 10 | G4: 10 | H4: 0 | I4: 0 | J4: 10 | K4: 0 | L4: 0 | M4: 0 | N4: 23 | O4: 7 | P4: 5 | Q4: 10 | R4: 10 | S4: 0 | T4: 0 | U4: 10 | V4: 0 | W4: 0 | X4: 0 | Y4: 21 | Z4: 5 | AA4: 5 | AB4: 10 | AC4: 10 | AD4: 0 | AE4: 0 | AF4: 10 | AG4: 0 | AH4: 0 | AI4: 0 | AJ4: =SUM(C4:AI4) -> 190 | AK4: =VLOOKUP(A4,'APPLICANTS 2023'!A:Q,2,FALSE) -> Zakwan G | AL4: =VLOOKUP(A4,'APPLICANTS 2023'!A:Q,3,FALSE) -> Abdul Rahman G | AM4: =VLOOKUP(A4,'APPLICANTS 2023'!A:Q,6,FALSE) -> 71 | AN4: =VLOOKUP(A4,'APPLICANTS 2023'!A:Q,7,FALSE) -> Jamia Darussalam Arabic College | AO4: =VLOOKUP(A4,'APPLICANTS 2023'!A:Q,9,FALSE) -> Oomerabad
A5: 556 | B5: 5 | C5: 23 | D5: 8 | E5: 5 | F5: 7 | G5: 10 | H5: 10 | I5: 0 | J5: 10 | K5: 8 | L5: 0 | M5: 0 | N5: 23 | O5: 8 | P5: 5 | Q5: 10 | R5: 10 | S5: 10 | T5: 0 | U5: 10 | V5: 7 | W5: 0 | X5: 0 | Y5: 25 | Z5: 7 | AA5: 5 | AB5: 7 | AC5: 10 | AD5: 10 | AE5: 0 | AF5: 10 | AG5: 8 | AH5: 0 | AI5: 0 | AJ5: =SUM(C5:AI5) -> 246 | AK5: =VLOOKUP(A5,'APPLICANTS 2023'!A:Q,2,FALSE) -> Saad | AL5: =VLOOKUP(A5,'APPLICANTS 2023'!A:Q,3,FALSE) -> Sirajur Rehaman | AM5: =VLOOKUP(A5,'APPLICANTS 2023'!A:Q,6,FALSE) -> 71 | AN5: =VLOOKUP(A5,'APPLICANTS 2023'!A:Q,7,FALSE) -> Jamia Darussalam Arabic College | AO5: =VLOOKUP(A5,'APPLICANTS 2023'!A:Q,9,FALSE) -> Oomerabad
A6: 562 | B6: 5 | C6: 0 | D6: 8 | E6: 5 | F6: 10 | G6: 10 | H6: 0 | I6: 0 | J6: 10 | K6: 8 | L6: 0 | M6: 0 | N6: 0 | O6: 5 | P6: 5 | Q6: 8 | R6: 10 | S6: 0 | T6: 0 | U6: 8 | V6: 10 | W6: 0 | X6: 0 | Y6: 0 | Z6: 7 | AA6: 5 | AB6: 8 | AC6: 9 | AD6: 0 | AE6: 0 | AF6: 8 | AG6: 9 | AH6: 0 | AI6: 0 | AJ6: =SUM(C6:AI6) -> 143 | AK6: =VLOOKUP(A6,'APPLICANTS 2023'!A:Q,2,FALSE) -> Umar H | AL6: =VLOOKUP(A6,'APPLICANTS 2023'!A:Q,3,FALSE) -> Hasan Ali | AM6: =VLOOKUP(A6,'APPLICANTS 2023'!A:Q,6,FALSE) -> 23 | AN6: =VLOOKUP(A6,'APPLICANTS 2023'!A:Q,7,FALSE) -> Ubay Ibn Ka'b Hifz Madarsa | AO6: =VLOOKUP(A6,'APPLICANTS 2023'!A:Q,9,FALSE) -> Dharmapuram
A7: 511 | B7: 5 | C7: 22 | D7: 8 | E7: 5 | F7: 10 | G7: 8 | H7: 10 | I7: 0 | J7: 5 | K7: 10 | L7: 8 | M7: 0 | N7: 24 | O7: 9 | P7: 5 | Q7: 9 | R7: 9 | S7: 10 | T7: 0 | U7: 6 | V7: 10 | W7: 9 | X7: 0 | Y7: 22 | Z7: 7 | AA7: 5 | AB7: 10 | AC7: 7 | AD7: 10 | AE7: 0 | AF7: 5 | AG7: 10 | AH7: 9 | AI7: 0 | AJ7: =SUM(C7:AI7) -> 262 | AK7: =VLOOKUP(A7,'APPLICANTS 2023'!A:Q,2,FALSE) -> Ahmed Ibrahim S | AL7: =VLOOKUP(A7,'APPLICANTS 2023'!A:Q,3,FALSE) -> Sahul Hameed | AM7: =VLOOKUP(A7,'APPLICANTS 2023'!A:Q,6,FALSE) -> 58 | AN7: =VLOOKUP(A7,'APPLICANTS 2023'!A:Q,7,FALSE) -> L.K.Higher Secondary School | AO7: =VLOOKUP(A7,'APPLICANTS 2023'!A:Q,9,FALSE) -> Kayalpatnam
A8: 553 | B8: 5 | C8: 0 | D8: 6 | E8: 5 | F8: 7 | G8: 8 | H8: 8 | I8: 0 | J8: 7 | K8: 0 | L8: 0 | M8: 0 | N8: 0 | O8: 0 | P8: 5 | Q8: 5 | R8: 8 | S8: 10 | T8: 0 | U8: 8 | V8: 0 | W8: 0 | X8: 0 | Y8: 0 | Z8: 0 | AA8: 5 | AB8: 8 | AC8: 6 | AD8: 8 | AE8: 0 | AF8: 9 | AG8: 0 | AH8: 0 | AI8: 0 | AJ8: =SUM(C8:AI8) -> 113 | AK8: =VLOOKUP(A8,'APPLICANTS 2023'!A:Q,2,FALSE) -> Muslim S | AL8: =VLOOKUP(A8,'APPLICANTS 2023'!A:Q,3,FALSE) -> Syed Sulaiman A | AM8: =VLOOKUP(A8,'APPLICANTS 2023'!A:Q,6,FALSE) -> 44 | AN8: =VLOOKUP(A8,'APPLICANTS 2023'!A:Q,7,FALSE) -> Madhrasathul Muslimeen Quran Memorizing School (JAQH) | AO8: =VLOOKUP(A8,'APPLICANTS 2023'!A:Q,9,FALSE) -> Tenkasi
A9: 517 | B9: 5 | C9: 25 | D9: 5 | E9: 5 | F9: 10 | G9: 10 | H9: 10 | I9: 0 | J9: 10 | K9: 10 | L9: 10 | M9: 0 | N9: 25 | O9: 10 | P9: 5 | Q9: 10 | R9: 10 | S9: 10 | T9: 0 | U9: 10 | V9: 10 | W9: 10 | X9: 0 | Y9: 23 | Z9: 7 | AA9: 5 | AB9: 10 | AC9: 10 | AD9: 10 | AE9: 0 | AF9: 10 | AG9: 10 | AH9: 7 | AI9: 0 | AJ9: =SUM(C9:AI9) -> 287 | AK9: =VLOOKUP(A9,'APPLICANTS 2023'!A:Q,2,FALSE) -> Anas Abdullah M.A | AL9: =VLOOKUP(A9,'APPLICANTS 2023'!A:Q,3,FALSE) -> Mogudoom Alaudeen H.M.F | AM9: =VLOOKUP(A9,'APPLICANTS 2023'!A:Q,6,FALSE) -> 60 | AN9: =VLOOKUP(A9,'APPLICANTS 2023'!A:Q,7,FALSE) -> Madarasathul Azhar Li Thahfeezil Quranil Kareem | AO9: =VLOOKUP(A9,'APPLICANTS 2023'!A:Q,9,FALSE) -> Kayalpatnam
A10: 527 | B10: 5 | C10: 21 | D10: 6 | E10: 5 | F10: 9 | G10: 0 | H10: 0 | I10: 0 | J10: 7 | K10: 0 | L10: 0 | M10: 0 | N10: 18 | O10: 5 | P10: 5 | Q10: 8 | R10: 0 | S10: 0 | T10: 0 | U10: 6 | V10: 0 | W10: 0 | X10: 0 | Y10: 16 | Z10: 5 | AA10: 5 | AB10: 5 | AC10: 0 | AD10: 0 | AE10: 0 | AF10: 6 | AG10: 0 | AH10: 0 | AI10: 0 | AJ10: =SUM(C10:AI10) -> 127 | AK10: =VLOOKUP(A10,'APPLICANTS 2023'!A:Q,2,FALSE) -> Mohamed Ibrahim T.S.M | AL10: =VLOOKUP(A10,'APPLICANTS 2023'!A:Q,3,FALSE) -> Mohamed Eassa T.A.S | AM10: =VLOOKUP(A10,'APPLICANTS 2023'!A:Q,6,FALSE) -> 27 | AN10: =VLOOKUP(A10,'APPLICANTS 2023'!A:Q,7,FALSE) -> Jannathul Firdowse Hifl Madrasa | AO10: =VLOOKUP(A10,'APPLICANTS 2023'!A:Q,9,FALSE) -> Madurai
A11: 535 | B11: 5 | C11: 25 | D11: 5 | E11: 5 | F11: 10 | G11: 10 | H11: 10 | I11: 0 | J11: 8 | K11: 10 | L11: 0 | M11: 0 | N11: 24 | O11: 6 | P11: 5 | Q11: 10 | R11: 10 | S11: 10 | T11: 0 | U11: 10 | V11: 8 | W11: 0 | X11: 0 | Y11: 22 | Z11: 5 | AA11: 5 | AB11: 10 | AC11: 10 | AD11: 10 | AE11: 0 | AF11: 10 | AG11: 10 | AH11: 0 | AI11: 0 | AJ11: =SUM(C11:AI11) -> 248 | AK11: =VLOOKUP(A11,'APPLICANTS 2023'!A:Q,2,FALSE) -> Mohammed Abubakkar Siddeiq M.S | AL11: =VLOOKUP(A11,'APPLICANTS 2023'!A:Q,3,FALSE) -> Mohammed Sulaiman | AM11: =VLOOKUP(A11,'APPLICANTS 2023'!A:Q,6,FALSE) -> 38 | AN11: =VLOOKUP(A11,'APPLICANTS 2023'!A:Q,7,FALSE) -> Madhrasa-E-Noorul Islam Arabic College | AO11: =VLOOKUP(A11,'APPLICANTS 2023'!A:Q,9,FALSE) -> Salem
A12: 1521 | B12: 15 | C12: 24 | D12: 9 | E12: 5 | F12: 7.5 | G12: 6 | H12: 6 | I12: 0 | J12: 6 | K12: 0 | L12: 0 | M12: 0 | N12: 20 | O12: 8 | P12: 4 | Q12: 7.5 | R12: 7.5 | S12: 5 | T12: 0 | U12: 7.5 | V12: 7.5 | W12: 4 | X12: 0 | Y12: 25 | Z12: 9 | AA12: 5 | AB12: 7.5 | AC12: 7.5 | AD12: 7.5 | AE12: 0 | AF12: 7.5 | AG12: 7.5 | AH12: 5 | AI12: 0 | AJ12: =SUM(C12:AI12) -> 216 | AK12: =VLOOKUP(A12,'APPLICANTS 2023'!A:Q,2,FALSE) -> Kifayathullah | AL12: =VLOOKUP(A12,'APPLICANTS 2023'!A:Q,3,FALSE) -> Abdul Gafoor | AM12: =VLOOKUP(A12,'APPLICANTS 2023'!A:Q,6,FALSE) -> 46 | AN12: =VLOOKUP(A12,'APPLICANTS 2023'!A:Q,7,FALSE) -> Al Madharasathul Salahiyya Arabic College | AO12: =VLOOKUP(A12,'APPLICANTS 2023'!A:Q,9,FALSE) -> Adirampattinam
A13: 1542 | B13: 15 | C13: 20 | D13: 9 | E13: 5 | F13: 6.5 | G13: 0 | H13: 0 | I13: 0 | J13: 7.5 | K13: 7.5 | L13: 7.5 | M13: 7.5 | N13: 20 | O13: 9 | P13: 5 | Q13: 7.5 | R13: 0 | S13: 7.5 | T13: 5 | U13: 0 | V13: 0 | W13: 2 | X13: 7.5 | Y13: 20 | Z13: 9 | AA13: 3 | AB13: 7.5 | AC13: 0 | AD13: 0 | AE13: 0 | AF13: 7.5 | AG13: 4.5 | AH13: 7.5 | AI13: 7.5 | AJ13: =SUM(C13:AI13) -> 200.5 | AK13: =VLOOKUP(A13,'APPLICANTS 2023'!A:Q,2,FALSE) -> Sufyan Bin Shamsuddeen | AL13: =VLOOKUP(A13,'APPLICANTS 2023'!A:Q,3,FALSE) -> Shamsuddeen | AM13: =VLOOKUP(A13,'APPLICANTS 2023'!A:Q,6,FALSE) -> 10 | AN13: =VLOOKUP(A13,'APPLICANTS 2023'!A:Q,7,FALSE) -> Unity Public School | AO13: =VLOOKUP(A13,'APPLICANTS 2023'!A:Q,9,FALSE) -> Chennai
... A31: 3031 | B31: 30 | C31: 23 | D31: 8 | E31: 5 | F31: 7.5 | G31: 7 | H31: 7.5 | I31: 0 | J31: 0 | K31: 0 | L31: 5 | M31: 0 | N31: 22 | O31: 7 | P31: 5 | Q31: 7.5 | R31: 7.5 | S31: 0 | T31: 0 | U31: 7.5 | V31: 7 | W31: 0 | X31: 0 | Y31: 18 | Z31: 8 | AA31: 3 | AB31: 7.5 | AC31: 7.5 | AD31: 0 | AE31: 0 | AF31: 7.5 | AG31: 5 | AH31: 0 | AI31: 0 | AJ31: =SUM(C31:AI31) -> 183 | AK31: =VLOOKUP(A31,'APPLICANTS 2023'!A:Q,2,FALSE) -> Mohamed Khalid | AL31: =VLOOKUP(A31,'APPLICANTS 2023'!A:Q,3,FALSE) -> Mohamed Dawood | AM31: =VLOOKUP(A31,'APPLICANTS 2023'!A:Q,6,FALSE) -> 69 | AN31: =VLOOKUP(A31,'APPLICANTS 2023'!A:Q,7,FALSE) -> Darul Uloom Faizul Islam | AO31: =VLOOKUP(A31,'APPLICANTS 2023'!A:Q,9,FALSE) -> Virinchipuram

Sheet A
A1: REG NO | B1: STAGE | C1: TOTAL | D1: NAME | E1: FATHER'S NAME | F1: I.NO | G1: I. Name | H1: TOWN | I1: J1 - HIFZ-1 | J1: J1 - HIFZ-2 | K1: J1 - TAJ -1 | L1: J1 - TAJ -2 | M1: J1 - ISMU -1 | N1: J1 - ISMU -2 | O1: J1 - MUTH -1 | P1: J1 - MUTH -2 | Q1: J1 - MUTH -3 | R1: J2 - HIFZ-1 | S1: J2 - HIFZ-2 | T1: J2 - TAJ -1 | U1: J2 - TAJ -2 | V1: J2 - ISMU -1 | W1: J2 - ISMU -2 | X1: J2 - MUTH -1 | Y1: J2 - MUTH -2 | Z1: J2 - MUTH -3
A2: 3045 | B2: A | C2: 190 | D2: Mohammed Talha | E2: Majeed Pasha | F2: 73 | G2: Madrasa E Imdadul Uloom | H2: Pernambut | I2: 19 | J2: 19 | K2: 8 | L2: 10 | M2: 5 | N2: 5 | O2: 10 | P2: 10 | Q2: 10 | R2: 20 | S2: 18 | T2: 8 | U2: 8 | V2: 5 | W2: 5 | X2: 10 | Y2: 10 | Z2: 10
A3: 3009 | B3: A | C3: 173 | D3: Abdullah M.S.H | E3: Mohammed Seyed Hashan M.A.K | F3: 06 | G3: Measi Matriculation Hr Sec School | H3: Chennai | I3: 20 | J3: 20 | K3: 9 | L3: 9 | M3: 5 | N3: 3 | O3: 10 | P3: 7 | Q3: 0 | R3: 20 | S3: 20 | T3: 9 | U3: 10 | V3: 0 | W3: 5 | X3: 10 | Y3: 8 | Z3: 8
A4: 3052 | B4: A | C4: 169 | D4: Muhammed Farooq M | E4: Mohamed Ebrahim | F4: 10 | G4: Unity Public School | H4: Chennai | I4: 13 | J4: 14 | K4: 5 | L4: 5 | M4: 5 | N4: 5 | O4: 10 | P4: 10 | Q4: 2 | R4: 20 | S4: 20 | T4: 10 | U4: 10 | V4: 5 | W4: 5 | X4: 10 | Y4: 10 | Z4: 10
A5: 3021 | B5: A | C5: 169 | D5: Hameed Afnaan M M | E5: Mohammed Mohiddin | F5: 58 | G5: L.K.Higher Secondary School | H5: Kayalpatnam | I5: 13 | J5: 12 | K5: 8 | L5: 9 | M5: 5 | N5: 5 | O5: 10 | P5: 10 | Q5: 10 | R5: 17 | S5: 16 | T5: 8 | U5: 6 | V5: 5 | W5: 5 | X5: 10 | Y5: 10 | Z5: 10
A6: 3049 | B6: A | C6: 169 | D6: Muddassir M.Y | E6: Mohamed Yousuf | F6: 49 | G6: Imam Shafi (rah) Matric Hr.Sec School | H6: Adirampattinam | I6: 15 | J6: 16 | K6: 10 | L6: 10 | M6: 5 | N6: 5 | O6: 10 | P6: 10 | Q6: 3 | R6: 18 | S6: 18 | T6: 8 | U6: 9 | V6: 5 | W6: 5 | X6: 8 | Y6: 8 | Z6: 6
A7: 3060 | B7: A | C7: 168 | D7: Sameer S | E7: Sulthan Basha | F7: 69 | G7: Darul Uloom Faizul Islam | H7: Virinchipuram | I7: 18 | J7: 18 | K7: 6 | L7: 6 | M7: 5 | N7: 5 | O7: 10 | P7: 10 | Q7: 0 | R7: 19 | S7: 19 | T7: 9 | U7: 9 | V7: 5 | W7: 5 | X7: 8 | Y7: 8 | Z7: 8
A8: 3019 | B8: A | C8: 156 | D8: Atheeq Mursi | E8: Abul Hasan Shaduly M.A | F8: 62 | G8: Malharul Fa'izeen | H8: Kayalpatnam | I8: 17 | J8: 15 | K8: 8 | L8: 8 | M8: 4 | N8: 4 | O8: 10 | P8: 10 | Q8: 0 | R8: 18 | S8: 18 | T8: 8 | U8: 8 | V8: 5 | W8: 5 | X8: 8 | Y8: 10 | Z8: 0
A9: 3010 | B9: A | C9: 154 | D9: Abdur Rahman | E9: Abdul Ghani | F9: 05 | G9: Madrasa Ubai Ibn Ka'b | H9: Chennai | I9: 20 | J9: 15 | K9: 10 | L9: 10 | M9: 5 | N9: 5 | O9: 10 | P9: 0 | Q9: 0 | R9: 18 | S9: 16 | T9: 8 | U9: 9 | V9: 5 | W9: 5 | X9: 8 | Y9: 5 | Z9: 5
A10: 3067 | B10: A | C10: 152 | D10: Yusuf Sahl K.F | E10: Farook Ali K.M | F10: 09 | G10: Sana Smart Matriculation School | H10: Chennai | I10: 15 | J10: 12 | K10: 4 | L10: 3 | M10: 3 | N10: 3 | O10: 10 | P10: 10 | Q10: 8 | R10: 17 | S10: 19 | T10: 8 | U10: 8 | V10: 5 | W10: 4 | X10: 8 | Y10: 8 | Z10: 7
